2025-04-08 19:29:32,018 [DEBUG] [req_id:427f243a-52da-409b-be56-fa1a3e7074e0 user:None] connection.py:951 - caching sha2: succeeded by fast path.
2025-04-08 19:29:32,093 [ERROR] [req_id:None user:None] handlers.py:101 - Unexpected server error: (pymysql.err.OperationalError) (1054, "Unknown column 'user.login_id' in 'field list'")
[SQL: SELECT user.nickname, user.email, user.login_id, user.phone, user.password, user.`role`, user.id, user.created_at, user.updated_at 
FROM user 
WHERE user.email = %s]
[parameters: ('jht@naver.com',)]
(Background on this error at: https://sqlalche.me/e/20/e3q8) | POST /auth/login/email
Traceback (most recent call last):
  File "c:\Users\jht56\anaconda3\envs\backend\lib\site-packages\sqlalchemy\engine\base.py", line 1964, in _exec_single_context
    self.dialect.do_execute(
  File "c:\Users\jht56\anaconda3\envs\backend\lib\site-packages\sqlalchemy\engine\default.py", line 945, in do_execute
    cursor.execute(statement, parameters)
  File "c:\Users\jht56\anaconda3\envs\backend\lib\site-packages\sqlalchemy\dialects\mysql\aiomysql.py", line 97, in execute
    return self.await_(self._execute_async(operation, parameters))
  File "c:\Users\jht56\anaconda3\envs\backend\lib\site-packages\sqlalchemy\util\_concurrency_py3k.py", line 132, in await_only
    return current.parent.switch(awaitable)  # type: ignore[no-any-return,attr-defined] # noqa: E501
  File "c:\Users\jht56\anaconda3\envs\backend\lib\site-packages\sqlalchemy\util\_concurrency_py3k.py", line 196, in greenlet_spawn
    value = await result
  File "c:\Users\jht56\anaconda3\envs\backend\lib\site-packages\sqlalchemy\dialects\mysql\aiomysql.py", line 106, in _execute_async
    result = await self._cursor.execute(operation, parameters)
  File "c:\Users\jht56\anaconda3\envs\backend\lib\site-packages\aiomysql\cursors.py", line 239, in execute
    await self._query(query)
  File "c:\Users\jht56\anaconda3\envs\backend\lib\site-packages\aiomysql\cursors.py", line 457, in _query
    await conn.query(q)
  File "c:\Users\jht56\anaconda3\envs\backend\lib\site-packages\aiomysql\connection.py", line 469, in query
    await self._read_query_result(unbuffered=unbuffered)
  File "c:\Users\jht56\anaconda3\envs\backend\lib\site-packages\aiomysql\connection.py", line 683, in _read_query_result
    await result.read()
  File "c:\Users\jht56\anaconda3\envs\backend\lib\site-packages\aiomysql\connection.py", line 1164, in read
    first_packet = await self.connection._read_packet()
  File "c:\Users\jht56\anaconda3\envs\backend\lib\site-packages\aiomysql\connection.py", line 652, in _read_packet
    packet.raise_for_error()
  File "c:\Users\jht56\anaconda3\envs\backend\lib\site-packages\pymysql\protocol.py", line 219, in raise_for_error
    err.raise_mysql_exception(self._data)
  File "c:\Users\jht56\anaconda3\envs\backend\lib\site-packages\pymysql\err.py", line 150, in raise_mysql_exception
    raise errorclass(errno, errval)
pymysql.err.OperationalError: (1054, "Unknown column 'user.login_id' in 'field list'")

The above exception was the direct cause of the following exception:

Traceback (most recent call last):
  File "c:\Users\jht56\anaconda3\envs\backend\lib\site-packages\starlette\middleware\errors.py", line 164, in __call__
    await self.app(scope, receive, _send)
  File "c:\Users\jht56\anaconda3\envs\backend\lib\site-packages\starlette\middleware\base.py", line 189, in __call__
    with collapse_excgroups():
  File "c:\Users\jht56\anaconda3\envs\backend\lib\contextlib.py", line 153, in __exit__
    self.gen.throw(typ, value, traceback)
  File "c:\Users\jht56\anaconda3\envs\backend\lib\site-packages\starlette\_utils.py", line 93, in collapse_excgroups
    raise exc
  File "c:\Users\jht56\anaconda3\envs\backend\lib\site-packages\starlette\middleware\base.py", line 191, in __call__
    response = await self.dispatch_func(request, call_next)
  File "C:\Users\jht56\Documents\GitHub\fastapi-core\src\common\middleware\base.py", line 51, in auth_middleware
    return await call_next(request)
  File "c:\Users\jht56\anaconda3\envs\backend\lib\site-packages\starlette\middleware\base.py", line 165, in call_next
    raise app_exc
  File "c:\Users\jht56\anaconda3\envs\backend\lib\site-packages\starlette\middleware\base.py", line 151, in coro
    await self.app(scope, receive_or_disconnect, send_no_error)
  File "c:\Users\jht56\anaconda3\envs\backend\lib\site-packages\starlette\middleware\base.py", line 189, in __call__
    with collapse_excgroups():
  File "c:\Users\jht56\anaconda3\envs\backend\lib\contextlib.py", line 153, in __exit__
    self.gen.throw(typ, value, traceback)
  File "c:\Users\jht56\anaconda3\envs\backend\lib\site-packages\starlette\_utils.py", line 93, in collapse_excgroups
    raise exc
  File "c:\Users\jht56\anaconda3\envs\backend\lib\site-packages\starlette\middleware\base.py", line 191, in __call__
    response = await self.dispatch_func(request, call_next)
  File "C:\Users\jht56\Documents\GitHub\fastapi-core\src\common\middleware\base.py", line 64, in redis_middleware
    return await call_next(request)
  File "c:\Users\jht56\anaconda3\envs\backend\lib\site-packages\starlette\middleware\base.py", line 165, in call_next
    raise app_exc
  File "c:\Users\jht56\anaconda3\envs\backend\lib\site-packages\starlette\middleware\base.py", line 151, in coro
    await self.app(scope, receive_or_disconnect, send_no_error)
  File "c:\Users\jht56\anaconda3\envs\backend\lib\site-packages\starlette\middleware\base.py", line 189, in __call__
    with collapse_excgroups():
  File "c:\Users\jht56\anaconda3\envs\backend\lib\contextlib.py", line 153, in __exit__
    self.gen.throw(typ, value, traceback)
  File "c:\Users\jht56\anaconda3\envs\backend\lib\site-packages\starlette\_utils.py", line 93, in collapse_excgroups
    raise exc
  File "c:\Users\jht56\anaconda3\envs\backend\lib\site-packages\starlette\middleware\base.py", line 191, in __call__
    response = await self.dispatch_func(request, call_next)
  File "C:\Users\jht56\Documents\GitHub\fastapi-core\src\common\middleware\base.py", line 42, in db_session_middleware
    response = await call_next(request)
  File "c:\Users\jht56\anaconda3\envs\backend\lib\site-packages\starlette\middleware\base.py", line 165, in call_next
    raise app_exc
  File "c:\Users\jht56\anaconda3\envs\backend\lib\site-packages\starlette\middleware\base.py", line 151, in coro
    await self.app(scope, receive_or_disconnect, send_no_error)
  File "c:\Users\jht56\anaconda3\envs\backend\lib\site-packages\starlette\middleware\base.py", line 189, in __call__
    with collapse_excgroups():
  File "c:\Users\jht56\anaconda3\envs\backend\lib\contextlib.py", line 153, in __exit__
    self.gen.throw(typ, value, traceback)
  File "c:\Users\jht56\anaconda3\envs\backend\lib\site-packages\starlette\_utils.py", line 93, in collapse_excgroups
    raise exc
  File "c:\Users\jht56\anaconda3\envs\backend\lib\site-packages\starlette\middleware\base.py", line 191, in __call__
    response = await self.dispatch_func(request, call_next)
  File "C:\Users\jht56\Documents\GitHub\fastapi-core\src\common\middleware\base.py", line 25, in log_context_middleware
    response = await call_next(request)
  File "c:\Users\jht56\anaconda3\envs\backend\lib\site-packages\starlette\middleware\base.py", line 165, in call_next
    raise app_exc
  File "c:\Users\jht56\anaconda3\envs\backend\lib\site-packages\starlette\middleware\base.py", line 151, in coro
    await self.app(scope, receive_or_disconnect, send_no_error)
  File "c:\Users\jht56\anaconda3\envs\backend\lib\site-packages\starlette\middleware\base.py", line 189, in __call__
    with collapse_excgroups():
  File "c:\Users\jht56\anaconda3\envs\backend\lib\contextlib.py", line 153, in __exit__
    self.gen.throw(typ, value, traceback)
  File "c:\Users\jht56\anaconda3\envs\backend\lib\site-packages\starlette\_utils.py", line 93, in collapse_excgroups
    raise exc
  File "c:\Users\jht56\anaconda3\envs\backend\lib\site-packages\starlette\middleware\base.py", line 191, in __call__
    response = await self.dispatch_func(request, call_next)
  File "C:\Users\jht56\Documents\GitHub\fastapi-core\src\common\middleware\base.py", line 32, in request_logger_middleware
    response = await call_next(request) #  여기까지가 다른 미들웨어들 먼저 실행됨
  File "c:\Users\jht56\anaconda3\envs\backend\lib\site-packages\starlette\middleware\base.py", line 165, in call_next
    raise app_exc
  File "c:\Users\jht56\anaconda3\envs\backend\lib\site-packages\starlette\middleware\base.py", line 151, in coro
    await self.app(scope, receive_or_disconnect, send_no_error)
  File "c:\Users\jht56\anaconda3\envs\backend\lib\site-packages\starlette\middleware\cors.py", line 85, in __call__
    await self.app(scope, receive, send)
  File "c:\Users\jht56\anaconda3\envs\backend\lib\site-packages\starlette\middleware\exceptions.py", line 65, in __call__
    await wrap_app_handling_exceptions(self.app, conn)(scope, receive, send)
  File "c:\Users\jht56\anaconda3\envs\backend\lib\site-packages\starlette\_exception_handler.py", line 64, in wrapped_app
    raise exc
  File "c:\Users\jht56\anaconda3\envs\backend\lib\site-packages\starlette\_exception_handler.py", line 53, in wrapped_app
    await app(scope, receive, sender)
  File "c:\Users\jht56\anaconda3\envs\backend\lib\site-packages\starlette\routing.py", line 756, in __call__
    await self.middleware_stack(scope, receive, send)
  File "c:\Users\jht56\anaconda3\envs\backend\lib\site-packages\starlette\routing.py", line 776, in app
    await route.handle(scope, receive, send)
  File "c:\Users\jht56\anaconda3\envs\backend\lib\site-packages\starlette\routing.py", line 297, in handle
    await self.app(scope, receive, send)
  File "c:\Users\jht56\anaconda3\envs\backend\lib\site-packages\starlette\routing.py", line 77, in app
    await wrap_app_handling_exceptions(app, request)(scope, receive, send)
  File "c:\Users\jht56\anaconda3\envs\backend\lib\site-packages\starlette\_exception_handler.py", line 64, in wrapped_app
    raise exc
  File "c:\Users\jht56\anaconda3\envs\backend\lib\site-packages\starlette\_exception_handler.py", line 53, in wrapped_app
    await app(scope, receive, sender)
  File "c:\Users\jht56\anaconda3\envs\backend\lib\site-packages\starlette\routing.py", line 72, in app
    response = await func(request)
  File "c:\Users\jht56\anaconda3\envs\backend\lib\site-packages\fastapi\routing.py", line 269, in app
    solved_result = await solve_dependencies(
  File "c:\Users\jht56\anaconda3\envs\backend\lib\site-packages\fastapi\dependencies\utils.py", line 600, in solve_dependencies
    solved = await call(**sub_values)
  File "C:\Users\jht56\Documents\GitHub\fastapi-core\src\auth\tokens\basic_token.py", line 39, in basic_token
    user = await auth_service.authenticate_with_field(field, identifier, password)
  File "C:\Users\jht56\Documents\GitHub\fastapi-core\src\auth\service.py", line 113, in authenticate_with_field
    user = await self.user_repository.get_user_by_field(field, identifier)
  File "C:\Users\jht56\Documents\GitHub\fastapi-core\src\user\repository.py", line 22, in get_user_by_field
    return await self.session.scalar(select(UserModel).where(column == value))
  File "c:\Users\jht56\anaconda3\envs\backend\lib\site-packages\sqlalchemy\ext\asyncio\session.py", line 519, in scalar
    return await greenlet_spawn(
  File "c:\Users\jht56\anaconda3\envs\backend\lib\site-packages\sqlalchemy\util\_concurrency_py3k.py", line 201, in greenlet_spawn
    result = context.throw(*sys.exc_info())
  File "c:\Users\jht56\anaconda3\envs\backend\lib\site-packages\sqlalchemy\orm\session.py", line 2413, in scalar
    return self._execute_internal(
  File "c:\Users\jht56\anaconda3\envs\backend\lib\site-packages\sqlalchemy\orm\session.py", line 2251, in _execute_internal
    result: Result[Any] = compile_state_cls.orm_execute_statement(
  File "c:\Users\jht56\anaconda3\envs\backend\lib\site-packages\sqlalchemy\orm\context.py", line 306, in orm_execute_statement
    result = conn.execute(
  File "c:\Users\jht56\anaconda3\envs\backend\lib\site-packages\sqlalchemy\engine\base.py", line 1416, in execute
    return meth(
  File "c:\Users\jht56\anaconda3\envs\backend\lib\site-packages\sqlalchemy\sql\elements.py", line 523, in _execute_on_connection
    return connection._execute_clauseelement(
  File "c:\Users\jht56\anaconda3\envs\backend\lib\site-packages\sqlalchemy\engine\base.py", line 1638, in _execute_clauseelement
    ret = self._execute_context(
  File "c:\Users\jht56\anaconda3\envs\backend\lib\site-packages\sqlalchemy\engine\base.py", line 1843, in _execute_context
    return self._exec_single_context(
  File "c:\Users\jht56\anaconda3\envs\backend\lib\site-packages\sqlalchemy\engine\base.py", line 1983, in _exec_single_context
    self._handle_dbapi_exception(
  File "c:\Users\jht56\anaconda3\envs\backend\lib\site-packages\sqlalchemy\engine\base.py", line 2352, in _handle_dbapi_exception
    raise sqlalchemy_exception.with_traceback(exc_info[2]) from e
  File "c:\Users\jht56\anaconda3\envs\backend\lib\site-packages\sqlalchemy\engine\base.py", line 1964, in _exec_single_context
    self.dialect.do_execute(
  File "c:\Users\jht56\anaconda3\envs\backend\lib\site-packages\sqlalchemy\engine\default.py", line 945, in do_execute
    cursor.execute(statement, parameters)
  File "c:\Users\jht56\anaconda3\envs\backend\lib\site-packages\sqlalchemy\dialects\mysql\aiomysql.py", line 97, in execute
    return self.await_(self._execute_async(operation, parameters))
  File "c:\Users\jht56\anaconda3\envs\backend\lib\site-packages\sqlalchemy\util\_concurrency_py3k.py", line 132, in await_only
    return current.parent.switch(awaitable)  # type: ignore[no-any-return,attr-defined] # noqa: E501
  File "c:\Users\jht56\anaconda3\envs\backend\lib\site-packages\sqlalchemy\util\_concurrency_py3k.py", line 196, in greenlet_spawn
    value = await result
  File "c:\Users\jht56\anaconda3\envs\backend\lib\site-packages\sqlalchemy\dialects\mysql\aiomysql.py", line 106, in _execute_async
    result = await self._cursor.execute(operation, parameters)
  File "c:\Users\jht56\anaconda3\envs\backend\lib\site-packages\aiomysql\cursors.py", line 239, in execute
    await self._query(query)
  File "c:\Users\jht56\anaconda3\envs\backend\lib\site-packages\aiomysql\cursors.py", line 457, in _query
    await conn.query(q)
  File "c:\Users\jht56\anaconda3\envs\backend\lib\site-packages\aiomysql\connection.py", line 469, in query
    await self._read_query_result(unbuffered=unbuffered)
  File "c:\Users\jht56\anaconda3\envs\backend\lib\site-packages\aiomysql\connection.py", line 683, in _read_query_result
    await result.read()
  File "c:\Users\jht56\anaconda3\envs\backend\lib\site-packages\aiomysql\connection.py", line 1164, in read
    first_packet = await self.connection._read_packet()
  File "c:\Users\jht56\anaconda3\envs\backend\lib\site-packages\aiomysql\connection.py", line 652, in _read_packet
    packet.raise_for_error()
  File "c:\Users\jht56\anaconda3\envs\backend\lib\site-packages\pymysql\protocol.py", line 219, in raise_for_error
    err.raise_mysql_exception(self._data)
  File "c:\Users\jht56\anaconda3\envs\backend\lib\site-packages\pymysql\err.py", line 150, in raise_mysql_exception
    raise errorclass(errno, errval)
sqlalchemy.exc.OperationalError: (pymysql.err.OperationalError) (1054, "Unknown column 'user.login_id' in 'field list'")
[SQL: SELECT user.nickname, user.email, user.login_id, user.phone, user.password, user.`role`, user.id, user.created_at, user.updated_at 
FROM user 
WHERE user.email = %s]
[parameters: ('jht@naver.com',)]
(Background on this error at: https://sqlalche.me/e/20/e3q8)
2025-04-08 19:30:05,598 [ERROR] [req_id:None user:None] handlers.py:101 - Unexpected server error: (pymysql.err.OperationalError) (1054, "Unknown column 'user.login_id' in 'field list'")
[SQL: SELECT user.nickname, user.email, user.login_id, user.phone, user.password, user.`role`, user.id, user.created_at, user.updated_at 
FROM user 
WHERE user.email = %s]
[parameters: ('jht@naver.com',)]
(Background on this error at: https://sqlalche.me/e/20/e3q8) | POST /auth/login/email
Traceback (most recent call last):
  File "c:\Users\jht56\anaconda3\envs\backend\lib\site-packages\sqlalchemy\engine\base.py", line 1964, in _exec_single_context
    self.dialect.do_execute(
  File "c:\Users\jht56\anaconda3\envs\backend\lib\site-packages\sqlalchemy\engine\default.py", line 945, in do_execute
    cursor.execute(statement, parameters)
  File "c:\Users\jht56\anaconda3\envs\backend\lib\site-packages\sqlalchemy\dialects\mysql\aiomysql.py", line 97, in execute
    return self.await_(self._execute_async(operation, parameters))
  File "c:\Users\jht56\anaconda3\envs\backend\lib\site-packages\sqlalchemy\util\_concurrency_py3k.py", line 132, in await_only
    return current.parent.switch(awaitable)  # type: ignore[no-any-return,attr-defined] # noqa: E501
  File "c:\Users\jht56\anaconda3\envs\backend\lib\site-packages\sqlalchemy\util\_concurrency_py3k.py", line 196, in greenlet_spawn
    value = await result
  File "c:\Users\jht56\anaconda3\envs\backend\lib\site-packages\sqlalchemy\dialects\mysql\aiomysql.py", line 106, in _execute_async
    result = await self._cursor.execute(operation, parameters)
  File "c:\Users\jht56\anaconda3\envs\backend\lib\site-packages\aiomysql\cursors.py", line 239, in execute
    await self._query(query)
  File "c:\Users\jht56\anaconda3\envs\backend\lib\site-packages\aiomysql\cursors.py", line 457, in _query
    await conn.query(q)
  File "c:\Users\jht56\anaconda3\envs\backend\lib\site-packages\aiomysql\connection.py", line 469, in query
    await self._read_query_result(unbuffered=unbuffered)
  File "c:\Users\jht56\anaconda3\envs\backend\lib\site-packages\aiomysql\connection.py", line 683, in _read_query_result
    await result.read()
  File "c:\Users\jht56\anaconda3\envs\backend\lib\site-packages\aiomysql\connection.py", line 1164, in read
    first_packet = await self.connection._read_packet()
  File "c:\Users\jht56\anaconda3\envs\backend\lib\site-packages\aiomysql\connection.py", line 652, in _read_packet
    packet.raise_for_error()
  File "c:\Users\jht56\anaconda3\envs\backend\lib\site-packages\pymysql\protocol.py", line 219, in raise_for_error
    err.raise_mysql_exception(self._data)
  File "c:\Users\jht56\anaconda3\envs\backend\lib\site-packages\pymysql\err.py", line 150, in raise_mysql_exception
    raise errorclass(errno, errval)
pymysql.err.OperationalError: (1054, "Unknown column 'user.login_id' in 'field list'")

The above exception was the direct cause of the following exception:

Traceback (most recent call last):
  File "c:\Users\jht56\anaconda3\envs\backend\lib\site-packages\starlette\middleware\errors.py", line 164, in __call__
    await self.app(scope, receive, _send)
  File "c:\Users\jht56\anaconda3\envs\backend\lib\site-packages\starlette\middleware\base.py", line 189, in __call__
    with collapse_excgroups():
  File "c:\Users\jht56\anaconda3\envs\backend\lib\contextlib.py", line 153, in __exit__
    self.gen.throw(typ, value, traceback)
  File "c:\Users\jht56\anaconda3\envs\backend\lib\site-packages\starlette\_utils.py", line 93, in collapse_excgroups
    raise exc
  File "c:\Users\jht56\anaconda3\envs\backend\lib\site-packages\starlette\middleware\base.py", line 191, in __call__
    response = await self.dispatch_func(request, call_next)
  File "C:\Users\jht56\Documents\GitHub\fastapi-core\src\common\middleware\base.py", line 51, in auth_middleware
    return await call_next(request)
  File "c:\Users\jht56\anaconda3\envs\backend\lib\site-packages\starlette\middleware\base.py", line 165, in call_next
    raise app_exc
  File "c:\Users\jht56\anaconda3\envs\backend\lib\site-packages\starlette\middleware\base.py", line 151, in coro
    await self.app(scope, receive_or_disconnect, send_no_error)
  File "c:\Users\jht56\anaconda3\envs\backend\lib\site-packages\starlette\middleware\base.py", line 189, in __call__
    with collapse_excgroups():
  File "c:\Users\jht56\anaconda3\envs\backend\lib\contextlib.py", line 153, in __exit__
    self.gen.throw(typ, value, traceback)
  File "c:\Users\jht56\anaconda3\envs\backend\lib\site-packages\starlette\_utils.py", line 93, in collapse_excgroups
    raise exc
  File "c:\Users\jht56\anaconda3\envs\backend\lib\site-packages\starlette\middleware\base.py", line 191, in __call__
    response = await self.dispatch_func(request, call_next)
  File "C:\Users\jht56\Documents\GitHub\fastapi-core\src\common\middleware\base.py", line 64, in redis_middleware
    return await call_next(request)
  File "c:\Users\jht56\anaconda3\envs\backend\lib\site-packages\starlette\middleware\base.py", line 165, in call_next
    raise app_exc
  File "c:\Users\jht56\anaconda3\envs\backend\lib\site-packages\starlette\middleware\base.py", line 151, in coro
    await self.app(scope, receive_or_disconnect, send_no_error)
  File "c:\Users\jht56\anaconda3\envs\backend\lib\site-packages\starlette\middleware\base.py", line 189, in __call__
    with collapse_excgroups():
  File "c:\Users\jht56\anaconda3\envs\backend\lib\contextlib.py", line 153, in __exit__
    self.gen.throw(typ, value, traceback)
  File "c:\Users\jht56\anaconda3\envs\backend\lib\site-packages\starlette\_utils.py", line 93, in collapse_excgroups
    raise exc
  File "c:\Users\jht56\anaconda3\envs\backend\lib\site-packages\starlette\middleware\base.py", line 191, in __call__
    response = await self.dispatch_func(request, call_next)
  File "C:\Users\jht56\Documents\GitHub\fastapi-core\src\common\middleware\base.py", line 42, in db_session_middleware
    response = await call_next(request)
  File "c:\Users\jht56\anaconda3\envs\backend\lib\site-packages\starlette\middleware\base.py", line 165, in call_next
    raise app_exc
  File "c:\Users\jht56\anaconda3\envs\backend\lib\site-packages\starlette\middleware\base.py", line 151, in coro
    await self.app(scope, receive_or_disconnect, send_no_error)
  File "c:\Users\jht56\anaconda3\envs\backend\lib\site-packages\starlette\middleware\base.py", line 189, in __call__
    with collapse_excgroups():
  File "c:\Users\jht56\anaconda3\envs\backend\lib\contextlib.py", line 153, in __exit__
    self.gen.throw(typ, value, traceback)
  File "c:\Users\jht56\anaconda3\envs\backend\lib\site-packages\starlette\_utils.py", line 93, in collapse_excgroups
    raise exc
  File "c:\Users\jht56\anaconda3\envs\backend\lib\site-packages\starlette\middleware\base.py", line 191, in __call__
    response = await self.dispatch_func(request, call_next)
  File "C:\Users\jht56\Documents\GitHub\fastapi-core\src\common\middleware\base.py", line 25, in log_context_middleware
    response = await call_next(request)
  File "c:\Users\jht56\anaconda3\envs\backend\lib\site-packages\starlette\middleware\base.py", line 165, in call_next
    raise app_exc
  File "c:\Users\jht56\anaconda3\envs\backend\lib\site-packages\starlette\middleware\base.py", line 151, in coro
    await self.app(scope, receive_or_disconnect, send_no_error)
  File "c:\Users\jht56\anaconda3\envs\backend\lib\site-packages\starlette\middleware\base.py", line 189, in __call__
    with collapse_excgroups():
  File "c:\Users\jht56\anaconda3\envs\backend\lib\contextlib.py", line 153, in __exit__
    self.gen.throw(typ, value, traceback)
  File "c:\Users\jht56\anaconda3\envs\backend\lib\site-packages\starlette\_utils.py", line 93, in collapse_excgroups
    raise exc
  File "c:\Users\jht56\anaconda3\envs\backend\lib\site-packages\starlette\middleware\base.py", line 191, in __call__
    response = await self.dispatch_func(request, call_next)
  File "C:\Users\jht56\Documents\GitHub\fastapi-core\src\common\middleware\base.py", line 32, in request_logger_middleware
    response = await call_next(request) #  여기까지가 다른 미들웨어들 먼저 실행됨
  File "c:\Users\jht56\anaconda3\envs\backend\lib\site-packages\starlette\middleware\base.py", line 165, in call_next
    raise app_exc
  File "c:\Users\jht56\anaconda3\envs\backend\lib\site-packages\starlette\middleware\base.py", line 151, in coro
    await self.app(scope, receive_or_disconnect, send_no_error)
  File "c:\Users\jht56\anaconda3\envs\backend\lib\site-packages\starlette\middleware\cors.py", line 85, in __call__
    await self.app(scope, receive, send)
  File "c:\Users\jht56\anaconda3\envs\backend\lib\site-packages\starlette\middleware\exceptions.py", line 65, in __call__
    await wrap_app_handling_exceptions(self.app, conn)(scope, receive, send)
  File "c:\Users\jht56\anaconda3\envs\backend\lib\site-packages\starlette\_exception_handler.py", line 64, in wrapped_app
    raise exc
  File "c:\Users\jht56\anaconda3\envs\backend\lib\site-packages\starlette\_exception_handler.py", line 53, in wrapped_app
    await app(scope, receive, sender)
  File "c:\Users\jht56\anaconda3\envs\backend\lib\site-packages\starlette\routing.py", line 756, in __call__
    await self.middleware_stack(scope, receive, send)
  File "c:\Users\jht56\anaconda3\envs\backend\lib\site-packages\starlette\routing.py", line 776, in app
    await route.handle(scope, receive, send)
  File "c:\Users\jht56\anaconda3\envs\backend\lib\site-packages\starlette\routing.py", line 297, in handle
    await self.app(scope, receive, send)
  File "c:\Users\jht56\anaconda3\envs\backend\lib\site-packages\starlette\routing.py", line 77, in app
    await wrap_app_handling_exceptions(app, request)(scope, receive, send)
  File "c:\Users\jht56\anaconda3\envs\backend\lib\site-packages\starlette\_exception_handler.py", line 64, in wrapped_app
    raise exc
  File "c:\Users\jht56\anaconda3\envs\backend\lib\site-packages\starlette\_exception_handler.py", line 53, in wrapped_app
    await app(scope, receive, sender)
  File "c:\Users\jht56\anaconda3\envs\backend\lib\site-packages\starlette\routing.py", line 72, in app
    response = await func(request)
  File "c:\Users\jht56\anaconda3\envs\backend\lib\site-packages\fastapi\routing.py", line 269, in app
    solved_result = await solve_dependencies(
  File "c:\Users\jht56\anaconda3\envs\backend\lib\site-packages\fastapi\dependencies\utils.py", line 600, in solve_dependencies
    solved = await call(**sub_values)
  File "C:\Users\jht56\Documents\GitHub\fastapi-core\src\auth\tokens\basic_token.py", line 39, in basic_token
    user = await auth_service.authenticate_with_field(field, identifier, password)
  File "C:\Users\jht56\Documents\GitHub\fastapi-core\src\auth\service.py", line 113, in authenticate_with_field
    user = await self.user_repository.get_user_by_field(field, identifier)
  File "C:\Users\jht56\Documents\GitHub\fastapi-core\src\user\repository.py", line 22, in get_user_by_field
    return await self.session.scalar(select(UserModel).where(column == value))
  File "c:\Users\jht56\anaconda3\envs\backend\lib\site-packages\sqlalchemy\ext\asyncio\session.py", line 519, in scalar
    return await greenlet_spawn(
  File "c:\Users\jht56\anaconda3\envs\backend\lib\site-packages\sqlalchemy\util\_concurrency_py3k.py", line 201, in greenlet_spawn
    result = context.throw(*sys.exc_info())
  File "c:\Users\jht56\anaconda3\envs\backend\lib\site-packages\sqlalchemy\orm\session.py", line 2413, in scalar
    return self._execute_internal(
  File "c:\Users\jht56\anaconda3\envs\backend\lib\site-packages\sqlalchemy\orm\session.py", line 2251, in _execute_internal
    result: Result[Any] = compile_state_cls.orm_execute_statement(
  File "c:\Users\jht56\anaconda3\envs\backend\lib\site-packages\sqlalchemy\orm\context.py", line 306, in orm_execute_statement
    result = conn.execute(
  File "c:\Users\jht56\anaconda3\envs\backend\lib\site-packages\sqlalchemy\engine\base.py", line 1416, in execute
    return meth(
  File "c:\Users\jht56\anaconda3\envs\backend\lib\site-packages\sqlalchemy\sql\elements.py", line 523, in _execute_on_connection
    return connection._execute_clauseelement(
  File "c:\Users\jht56\anaconda3\envs\backend\lib\site-packages\sqlalchemy\engine\base.py", line 1638, in _execute_clauseelement
    ret = self._execute_context(
  File "c:\Users\jht56\anaconda3\envs\backend\lib\site-packages\sqlalchemy\engine\base.py", line 1843, in _execute_context
    return self._exec_single_context(
  File "c:\Users\jht56\anaconda3\envs\backend\lib\site-packages\sqlalchemy\engine\base.py", line 1983, in _exec_single_context
    self._handle_dbapi_exception(
  File "c:\Users\jht56\anaconda3\envs\backend\lib\site-packages\sqlalchemy\engine\base.py", line 2352, in _handle_dbapi_exception
    raise sqlalchemy_exception.with_traceback(exc_info[2]) from e
  File "c:\Users\jht56\anaconda3\envs\backend\lib\site-packages\sqlalchemy\engine\base.py", line 1964, in _exec_single_context
    self.dialect.do_execute(
  File "c:\Users\jht56\anaconda3\envs\backend\lib\site-packages\sqlalchemy\engine\default.py", line 945, in do_execute
    cursor.execute(statement, parameters)
  File "c:\Users\jht56\anaconda3\envs\backend\lib\site-packages\sqlalchemy\dialects\mysql\aiomysql.py", line 97, in execute
    return self.await_(self._execute_async(operation, parameters))
  File "c:\Users\jht56\anaconda3\envs\backend\lib\site-packages\sqlalchemy\util\_concurrency_py3k.py", line 132, in await_only
    return current.parent.switch(awaitable)  # type: ignore[no-any-return,attr-defined] # noqa: E501
  File "c:\Users\jht56\anaconda3\envs\backend\lib\site-packages\sqlalchemy\util\_concurrency_py3k.py", line 196, in greenlet_spawn
    value = await result
  File "c:\Users\jht56\anaconda3\envs\backend\lib\site-packages\sqlalchemy\dialects\mysql\aiomysql.py", line 106, in _execute_async
    result = await self._cursor.execute(operation, parameters)
  File "c:\Users\jht56\anaconda3\envs\backend\lib\site-packages\aiomysql\cursors.py", line 239, in execute
    await self._query(query)
  File "c:\Users\jht56\anaconda3\envs\backend\lib\site-packages\aiomysql\cursors.py", line 457, in _query
    await conn.query(q)
  File "c:\Users\jht56\anaconda3\envs\backend\lib\site-packages\aiomysql\connection.py", line 469, in query
    await self._read_query_result(unbuffered=unbuffered)
  File "c:\Users\jht56\anaconda3\envs\backend\lib\site-packages\aiomysql\connection.py", line 683, in _read_query_result
    await result.read()
  File "c:\Users\jht56\anaconda3\envs\backend\lib\site-packages\aiomysql\connection.py", line 1164, in read
    first_packet = await self.connection._read_packet()
  File "c:\Users\jht56\anaconda3\envs\backend\lib\site-packages\aiomysql\connection.py", line 652, in _read_packet
    packet.raise_for_error()
  File "c:\Users\jht56\anaconda3\envs\backend\lib\site-packages\pymysql\protocol.py", line 219, in raise_for_error
    err.raise_mysql_exception(self._data)
  File "c:\Users\jht56\anaconda3\envs\backend\lib\site-packages\pymysql\err.py", line 150, in raise_mysql_exception
    raise errorclass(errno, errval)
sqlalchemy.exc.OperationalError: (pymysql.err.OperationalError) (1054, "Unknown column 'user.login_id' in 'field list'")
[SQL: SELECT user.nickname, user.email, user.login_id, user.phone, user.password, user.`role`, user.id, user.created_at, user.updated_at 
FROM user 
WHERE user.email = %s]
[parameters: ('jht@naver.com',)]
(Background on this error at: https://sqlalche.me/e/20/e3q8)
2025-04-08 19:30:59,295 [INFO] [req_id:7b828b97-ac6c-4e53-95a2-cf8c5d0711f2 user:None] base.py:35 - POST /auth/login/email [200] 0.1338s
2025-04-08 19:31:25,947 [INFO] [req_id:cce79733-2c7d-4663-901a-bc24d4e42dfe user:None] base.py:35 - POST /auth/login/email [200] 0.0931s
2025-04-08 19:31:37,983 [INFO] [req_id:87f93922-dec9-440e-bed3-2f1696cd0778 user:1] base.py:35 - POST /auth/logout [200] 0.0076s
2025-04-08 19:31:56,229 [ERROR] [req_id:None user:None] handlers.py:101 - Unexpected server error: 401: 토큰이 만료되었습니다. | POST /auth/token/access
  + Exception Group Traceback (most recent call last):
  |   File "c:\Users\jht56\anaconda3\envs\backend\lib\site-packages\starlette\_utils.py", line 87, in collapse_excgroups
  |     yield
  |   File "c:\Users\jht56\anaconda3\envs\backend\lib\site-packages\starlette\middleware\base.py", line 190, in __call__
  |     async with anyio.create_task_group() as task_group:
  |   File "c:\Users\jht56\anaconda3\envs\backend\lib\site-packages\anyio\_backends\_asyncio.py", line 767, in __aexit__
  |     raise BaseExceptionGroup(
  | exceptiongroup.ExceptionGroup: unhandled errors in a TaskGroup (1 sub-exception)
  +-+---------------- 1 ----------------
    | Traceback (most recent call last):
    |   File "c:\Users\jht56\anaconda3\envs\backend\lib\site-packages\starlette\middleware\errors.py", line 164, in __call__
    |     await self.app(scope, receive, _send)
    |   File "c:\Users\jht56\anaconda3\envs\backend\lib\site-packages\starlette\middleware\base.py", line 189, in __call__
    |     with collapse_excgroups():
    |   File "c:\Users\jht56\anaconda3\envs\backend\lib\contextlib.py", line 153, in __exit__
    |     self.gen.throw(typ, value, traceback)
    |   File "c:\Users\jht56\anaconda3\envs\backend\lib\site-packages\starlette\_utils.py", line 93, in collapse_excgroups
    |     raise exc
    |   File "c:\Users\jht56\anaconda3\envs\backend\lib\site-packages\starlette\middleware\base.py", line 191, in __call__
    |     response = await self.dispatch_func(request, call_next)
    |   File "C:\Users\jht56\Documents\GitHub\fastapi-core\src\common\middleware\base.py", line 55, in auth_middleware
    |     user = decode_jwt_token(token) if token else None
    |   File "C:\Users\jht56\Documents\GitHub\fastapi-core\src\auth\service.py", line 182, in decode_jwt_token
    |     raise HTTPException(status_code=401, detail="토큰이 만료되었습니다.")
    | fastapi.exceptions.HTTPException: 401: 토큰이 만료되었습니다.
    +------------------------------------

During handling of the above exception, another exception occurred:

Traceback (most recent call last):
  File "c:\Users\jht56\anaconda3\envs\backend\lib\site-packages\starlette\middleware\errors.py", line 164, in __call__
    await self.app(scope, receive, _send)
  File "c:\Users\jht56\anaconda3\envs\backend\lib\site-packages\starlette\middleware\base.py", line 189, in __call__
    with collapse_excgroups():
  File "c:\Users\jht56\anaconda3\envs\backend\lib\contextlib.py", line 153, in __exit__
    self.gen.throw(typ, value, traceback)
  File "c:\Users\jht56\anaconda3\envs\backend\lib\site-packages\starlette\_utils.py", line 93, in collapse_excgroups
    raise exc
  File "c:\Users\jht56\anaconda3\envs\backend\lib\site-packages\starlette\middleware\base.py", line 191, in __call__
    response = await self.dispatch_func(request, call_next)
  File "C:\Users\jht56\Documents\GitHub\fastapi-core\src\common\middleware\base.py", line 55, in auth_middleware
    user = decode_jwt_token(token) if token else None
  File "C:\Users\jht56\Documents\GitHub\fastapi-core\src\auth\service.py", line 182, in decode_jwt_token
    raise HTTPException(status_code=401, detail="토큰이 만료되었습니다.")
fastapi.exceptions.HTTPException: 401: 토큰이 만료되었습니다.
2025-04-08 19:47:22,162 [ERROR] [req_id:None user:None] handlers.py:101 - Unexpected server error: 401: 토큰이 만료되었습니다. | POST /auth/token/access
  + Exception Group Traceback (most recent call last):
  |   File "c:\Users\jht56\anaconda3\envs\backend\lib\site-packages\starlette\_utils.py", line 87, in collapse_excgroups
  |     yield
  |   File "c:\Users\jht56\anaconda3\envs\backend\lib\site-packages\starlette\middleware\base.py", line 190, in __call__
  |     async with anyio.create_task_group() as task_group:
  |   File "c:\Users\jht56\anaconda3\envs\backend\lib\site-packages\anyio\_backends\_asyncio.py", line 767, in __aexit__
  |     raise BaseExceptionGroup(
  | exceptiongroup.ExceptionGroup: unhandled errors in a TaskGroup (1 sub-exception)
  +-+---------------- 1 ----------------
    | Traceback (most recent call last):
    |   File "c:\Users\jht56\anaconda3\envs\backend\lib\site-packages\starlette\middleware\errors.py", line 164, in __call__
    |     await self.app(scope, receive, _send)
    |   File "c:\Users\jht56\anaconda3\envs\backend\lib\site-packages\starlette\middleware\base.py", line 189, in __call__
    |     with collapse_excgroups():
    |   File "c:\Users\jht56\anaconda3\envs\backend\lib\contextlib.py", line 153, in __exit__
    |     self.gen.throw(typ, value, traceback)
    |   File "c:\Users\jht56\anaconda3\envs\backend\lib\site-packages\starlette\_utils.py", line 93, in collapse_excgroups
    |     raise exc
    |   File "c:\Users\jht56\anaconda3\envs\backend\lib\site-packages\starlette\middleware\base.py", line 191, in __call__
    |     response = await self.dispatch_func(request, call_next)
    |   File "C:\Users\jht56\Documents\GitHub\fastapi-core\src\common\middleware\base.py", line 55, in auth_middleware
    |     logger.exception("Unhandled exception in db_session_middleware")
    |   File "C:\Users\jht56\Documents\GitHub\fastapi-core\src\auth\service.py", line 182, in decode_jwt_token
    |     raise HTTPException(status_code=401, detail="토큰이 만료되었습니다.")
    | fastapi.exceptions.HTTPException: 401: 토큰이 만료되었습니다.
    +------------------------------------

During handling of the above exception, another exception occurred:

Traceback (most recent call last):
  File "c:\Users\jht56\anaconda3\envs\backend\lib\site-packages\starlette\middleware\errors.py", line 164, in __call__
    await self.app(scope, receive, _send)
  File "c:\Users\jht56\anaconda3\envs\backend\lib\site-packages\starlette\middleware\base.py", line 189, in __call__
    with collapse_excgroups():
  File "c:\Users\jht56\anaconda3\envs\backend\lib\contextlib.py", line 153, in __exit__
    self.gen.throw(typ, value, traceback)
  File "c:\Users\jht56\anaconda3\envs\backend\lib\site-packages\starlette\_utils.py", line 93, in collapse_excgroups
    raise exc
  File "c:\Users\jht56\anaconda3\envs\backend\lib\site-packages\starlette\middleware\base.py", line 191, in __call__
    response = await self.dispatch_func(request, call_next)
  File "C:\Users\jht56\Documents\GitHub\fastapi-core\src\common\middleware\base.py", line 55, in auth_middleware
    logger.exception("Unhandled exception in db_session_middleware")
  File "C:\Users\jht56\Documents\GitHub\fastapi-core\src\auth\service.py", line 182, in decode_jwt_token
    raise HTTPException(status_code=401, detail="토큰이 만료되었습니다.")
fastapi.exceptions.HTTPException: 401: 토큰이 만료되었습니다.
2025-04-08 19:47:26,502 [ERROR] [req_id:None user:None] handlers.py:101 - Unexpected server error: 401: 토큰이 만료되었습니다. | POST /auth/token/access
  + Exception Group Traceback (most recent call last):
  |   File "c:\Users\jht56\anaconda3\envs\backend\lib\site-packages\starlette\_utils.py", line 87, in collapse_excgroups
  |     yield
  |   File "c:\Users\jht56\anaconda3\envs\backend\lib\site-packages\starlette\middleware\base.py", line 190, in __call__
  |     async with anyio.create_task_group() as task_group:
  |   File "c:\Users\jht56\anaconda3\envs\backend\lib\site-packages\anyio\_backends\_asyncio.py", line 767, in __aexit__
  |     raise BaseExceptionGroup(
  | exceptiongroup.ExceptionGroup: unhandled errors in a TaskGroup (1 sub-exception)
  +-+---------------- 1 ----------------
    | Traceback (most recent call last):
    |   File "c:\Users\jht56\anaconda3\envs\backend\lib\site-packages\starlette\middleware\errors.py", line 164, in __call__
    |     await self.app(scope, receive, _send)
    |   File "c:\Users\jht56\anaconda3\envs\backend\lib\site-packages\starlette\middleware\base.py", line 189, in __call__
    |     with collapse_excgroups():
    |   File "c:\Users\jht56\anaconda3\envs\backend\lib\contextlib.py", line 153, in __exit__
    |     self.gen.throw(typ, value, traceback)
    |   File "c:\Users\jht56\anaconda3\envs\backend\lib\site-packages\starlette\_utils.py", line 93, in collapse_excgroups
    |     raise exc
    |   File "c:\Users\jht56\anaconda3\envs\backend\lib\site-packages\starlette\middleware\base.py", line 191, in __call__
    |     response = await self.dispatch_func(request, call_next)
    |   File "C:\Users\jht56\Documents\GitHub\fastapi-core\src\common\middleware\base.py", line 68, in auth_middleware
    |     user = decode_jwt_token(token) if token else None
    |   File "C:\Users\jht56\Documents\GitHub\fastapi-core\src\auth\service.py", line 182, in decode_jwt_token
    |     raise HTTPException(status_code=401, detail="토큰이 만료되었습니다.")
    | fastapi.exceptions.HTTPException: 401: 토큰이 만료되었습니다.
    +------------------------------------

During handling of the above exception, another exception occurred:

Traceback (most recent call last):
  File "c:\Users\jht56\anaconda3\envs\backend\lib\site-packages\starlette\middleware\errors.py", line 164, in __call__
    await self.app(scope, receive, _send)
  File "c:\Users\jht56\anaconda3\envs\backend\lib\site-packages\starlette\middleware\base.py", line 189, in __call__
    with collapse_excgroups():
  File "c:\Users\jht56\anaconda3\envs\backend\lib\contextlib.py", line 153, in __exit__
    self.gen.throw(typ, value, traceback)
  File "c:\Users\jht56\anaconda3\envs\backend\lib\site-packages\starlette\_utils.py", line 93, in collapse_excgroups
    raise exc
  File "c:\Users\jht56\anaconda3\envs\backend\lib\site-packages\starlette\middleware\base.py", line 191, in __call__
    response = await self.dispatch_func(request, call_next)
  File "C:\Users\jht56\Documents\GitHub\fastapi-core\src\common\middleware\base.py", line 68, in auth_middleware
    user = decode_jwt_token(token) if token else None
  File "C:\Users\jht56\Documents\GitHub\fastapi-core\src\auth\service.py", line 182, in decode_jwt_token
    raise HTTPException(status_code=401, detail="토큰이 만료되었습니다.")
fastapi.exceptions.HTTPException: 401: 토큰이 만료되었습니다.
2025-04-08 19:47:28,939 [ERROR] [req_id:None user:None] handlers.py:101 - Unexpected server error: 401: 토큰이 만료되었습니다. | POST /auth/token/access
  + Exception Group Traceback (most recent call last):
  |   File "c:\Users\jht56\anaconda3\envs\backend\lib\site-packages\starlette\_utils.py", line 87, in collapse_excgroups
  |     yield
  |   File "c:\Users\jht56\anaconda3\envs\backend\lib\site-packages\starlette\middleware\base.py", line 190, in __call__
  |     async with anyio.create_task_group() as task_group:
  |   File "c:\Users\jht56\anaconda3\envs\backend\lib\site-packages\anyio\_backends\_asyncio.py", line 767, in __aexit__
  |     raise BaseExceptionGroup(
  | exceptiongroup.ExceptionGroup: unhandled errors in a TaskGroup (1 sub-exception)
  +-+---------------- 1 ----------------
    | Traceback (most recent call last):
    |   File "c:\Users\jht56\anaconda3\envs\backend\lib\site-packages\starlette\middleware\errors.py", line 164, in __call__
    |     await self.app(scope, receive, _send)
    |   File "c:\Users\jht56\anaconda3\envs\backend\lib\site-packages\starlette\middleware\base.py", line 189, in __call__
    |     with collapse_excgroups():
    |   File "c:\Users\jht56\anaconda3\envs\backend\lib\contextlib.py", line 153, in __exit__
    |     self.gen.throw(typ, value, traceback)
    |   File "c:\Users\jht56\anaconda3\envs\backend\lib\site-packages\starlette\_utils.py", line 93, in collapse_excgroups
    |     raise exc
    |   File "c:\Users\jht56\anaconda3\envs\backend\lib\site-packages\starlette\middleware\base.py", line 191, in __call__
    |     response = await self.dispatch_func(request, call_next)
    |   File "C:\Users\jht56\Documents\GitHub\fastapi-core\src\common\middleware\base.py", line 68, in auth_middleware
    |     user = decode_jwt_token(token) if token else None
    |   File "C:\Users\jht56\Documents\GitHub\fastapi-core\src\auth\service.py", line 182, in decode_jwt_token
    |     raise HTTPException(status_code=401, detail="토큰이 만료되었습니다.")
    | fastapi.exceptions.HTTPException: 401: 토큰이 만료되었습니다.
    +------------------------------------

During handling of the above exception, another exception occurred:

Traceback (most recent call last):
  File "c:\Users\jht56\anaconda3\envs\backend\lib\site-packages\starlette\middleware\errors.py", line 164, in __call__
    await self.app(scope, receive, _send)
  File "c:\Users\jht56\anaconda3\envs\backend\lib\site-packages\starlette\middleware\base.py", line 189, in __call__
    with collapse_excgroups():
  File "c:\Users\jht56\anaconda3\envs\backend\lib\contextlib.py", line 153, in __exit__
    self.gen.throw(typ, value, traceback)
  File "c:\Users\jht56\anaconda3\envs\backend\lib\site-packages\starlette\_utils.py", line 93, in collapse_excgroups
    raise exc
  File "c:\Users\jht56\anaconda3\envs\backend\lib\site-packages\starlette\middleware\base.py", line 191, in __call__
    response = await self.dispatch_func(request, call_next)
  File "C:\Users\jht56\Documents\GitHub\fastapi-core\src\common\middleware\base.py", line 68, in auth_middleware
    user = decode_jwt_token(token) if token else None
  File "C:\Users\jht56\Documents\GitHub\fastapi-core\src\auth\service.py", line 182, in decode_jwt_token
    raise HTTPException(status_code=401, detail="토큰이 만료되었습니다.")
fastapi.exceptions.HTTPException: 401: 토큰이 만료되었습니다.
2025-04-08 19:47:46,282 [ERROR] [req_id:None user:None] handlers.py:101 - Unexpected server error: 401: 토큰이 만료되었습니다. | POST /auth/token/access
  + Exception Group Traceback (most recent call last):
  |   File "c:\Users\jht56\anaconda3\envs\backend\lib\site-packages\starlette\_utils.py", line 87, in collapse_excgroups
  |     yield
  |   File "c:\Users\jht56\anaconda3\envs\backend\lib\site-packages\starlette\middleware\base.py", line 190, in __call__
  |     async with anyio.create_task_group() as task_group:
  |   File "c:\Users\jht56\anaconda3\envs\backend\lib\site-packages\anyio\_backends\_asyncio.py", line 767, in __aexit__
  |     raise BaseExceptionGroup(
  | exceptiongroup.ExceptionGroup: unhandled errors in a TaskGroup (1 sub-exception)
  +-+---------------- 1 ----------------
    | Traceback (most recent call last):
    |   File "c:\Users\jht56\anaconda3\envs\backend\lib\site-packages\starlette\middleware\errors.py", line 164, in __call__
    |     await self.app(scope, receive, _send)
    |   File "c:\Users\jht56\anaconda3\envs\backend\lib\site-packages\starlette\middleware\base.py", line 189, in __call__
    |     with collapse_excgroups():
    |   File "c:\Users\jht56\anaconda3\envs\backend\lib\contextlib.py", line 153, in __exit__
    |     self.gen.throw(typ, value, traceback)
    |   File "c:\Users\jht56\anaconda3\envs\backend\lib\site-packages\starlette\_utils.py", line 93, in collapse_excgroups
    |     raise exc
    |   File "c:\Users\jht56\anaconda3\envs\backend\lib\site-packages\starlette\middleware\base.py", line 191, in __call__
    |     response = await self.dispatch_func(request, call_next)
    |   File "C:\Users\jht56\Documents\GitHub\fastapi-core\src\common\middleware\base.py", line 68, in auth_middleware
    |     user = decode_jwt_token(token) if token else None
    |   File "C:\Users\jht56\Documents\GitHub\fastapi-core\src\auth\service.py", line 182, in decode_jwt_token
    |     raise HTTPException(status_code=401, detail="토큰이 만료되었습니다.")
    | fastapi.exceptions.HTTPException: 401: 토큰이 만료되었습니다.
    +------------------------------------

During handling of the above exception, another exception occurred:

Traceback (most recent call last):
  File "c:\Users\jht56\anaconda3\envs\backend\lib\site-packages\starlette\middleware\errors.py", line 164, in __call__
    await self.app(scope, receive, _send)
  File "c:\Users\jht56\anaconda3\envs\backend\lib\site-packages\starlette\middleware\base.py", line 189, in __call__
    with collapse_excgroups():
  File "c:\Users\jht56\anaconda3\envs\backend\lib\contextlib.py", line 153, in __exit__
    self.gen.throw(typ, value, traceback)
  File "c:\Users\jht56\anaconda3\envs\backend\lib\site-packages\starlette\_utils.py", line 93, in collapse_excgroups
    raise exc
  File "c:\Users\jht56\anaconda3\envs\backend\lib\site-packages\starlette\middleware\base.py", line 191, in __call__
    response = await self.dispatch_func(request, call_next)
  File "C:\Users\jht56\Documents\GitHub\fastapi-core\src\common\middleware\base.py", line 68, in auth_middleware
    user = decode_jwt_token(token) if token else None
  File "C:\Users\jht56\Documents\GitHub\fastapi-core\src\auth\service.py", line 182, in decode_jwt_token
    raise HTTPException(status_code=401, detail="토큰이 만료되었습니다.")
fastapi.exceptions.HTTPException: 401: 토큰이 만료되었습니다.
2025-04-08 19:55:50,323 [ERROR] [req_id:None user:None] handlers.py:101 - Unexpected server error: 401: 토큰이 만료되었습니다. | POST /auth/token/access
  + Exception Group Traceback (most recent call last):
  |   File "c:\Users\jht56\anaconda3\envs\backend\lib\site-packages\starlette\_utils.py", line 87, in collapse_excgroups
  |     yield
  |   File "c:\Users\jht56\anaconda3\envs\backend\lib\site-packages\starlette\middleware\base.py", line 190, in __call__
  |     async with anyio.create_task_group() as task_group:
  |   File "c:\Users\jht56\anaconda3\envs\backend\lib\site-packages\anyio\_backends\_asyncio.py", line 767, in __aexit__
  |     raise BaseExceptionGroup(
  | exceptiongroup.ExceptionGroup: unhandled errors in a TaskGroup (1 sub-exception)
  +-+---------------- 1 ----------------
    | Traceback (most recent call last):
    |   File "c:\Users\jht56\anaconda3\envs\backend\lib\site-packages\starlette\middleware\errors.py", line 164, in __call__
    |     await self.app(scope, receive, _send)
    |   File "c:\Users\jht56\anaconda3\envs\backend\lib\site-packages\starlette\middleware\base.py", line 189, in __call__
    |     with collapse_excgroups():
    |   File "c:\Users\jht56\anaconda3\envs\backend\lib\contextlib.py", line 153, in __exit__
    |     self.gen.throw(typ, value, traceback)
    |   File "c:\Users\jht56\anaconda3\envs\backend\lib\site-packages\starlette\_utils.py", line 93, in collapse_excgroups
    |     raise exc
    |   File "c:\Users\jht56\anaconda3\envs\backend\lib\site-packages\starlette\middleware\base.py", line 191, in __call__
    |     response = await self.dispatch_func(request, call_next)
    |   File "C:\Users\jht56\Documents\GitHub\fastapi-core\src\common\middleware\base.py", line 68, in auth_middleware
    |     user = decode_jwt_token(token) if token else None
    |   File "C:\Users\jht56\Documents\GitHub\fastapi-core\src\auth\service.py", line 183, in decode_jwt_token
    |     except jwt.ExpiredSignatureError:
    | common.exceptions.base.UnauthorizedException: 401: 토큰이 만료되었습니다.
    +------------------------------------

During handling of the above exception, another exception occurred:

Traceback (most recent call last):
  File "c:\Users\jht56\anaconda3\envs\backend\lib\site-packages\starlette\middleware\errors.py", line 164, in __call__
    await self.app(scope, receive, _send)
  File "c:\Users\jht56\anaconda3\envs\backend\lib\site-packages\starlette\middleware\base.py", line 189, in __call__
    with collapse_excgroups():
  File "c:\Users\jht56\anaconda3\envs\backend\lib\contextlib.py", line 153, in __exit__
    self.gen.throw(typ, value, traceback)
  File "c:\Users\jht56\anaconda3\envs\backend\lib\site-packages\starlette\_utils.py", line 93, in collapse_excgroups
    raise exc
  File "c:\Users\jht56\anaconda3\envs\backend\lib\site-packages\starlette\middleware\base.py", line 191, in __call__
    response = await self.dispatch_func(request, call_next)
  File "C:\Users\jht56\Documents\GitHub\fastapi-core\src\common\middleware\base.py", line 68, in auth_middleware
    user = decode_jwt_token(token) if token else None
  File "C:\Users\jht56\Documents\GitHub\fastapi-core\src\auth\service.py", line 183, in decode_jwt_token
    except jwt.ExpiredSignatureError:
common.exceptions.base.UnauthorizedException: 401: 토큰이 만료되었습니다.
2025-04-08 19:56:25,357 [ERROR] [req_id:None user:None] handlers.py:101 - Unexpected server error: 401: 토큰이 만료되었습니다. | POST /auth/token/access
  + Exception Group Traceback (most recent call last):
  |   File "c:\Users\jht56\anaconda3\envs\backend\lib\site-packages\starlette\_utils.py", line 87, in collapse_excgroups
  |     yield
  |   File "c:\Users\jht56\anaconda3\envs\backend\lib\site-packages\starlette\middleware\base.py", line 190, in __call__
  |     async with anyio.create_task_group() as task_group:
  |   File "c:\Users\jht56\anaconda3\envs\backend\lib\site-packages\anyio\_backends\_asyncio.py", line 767, in __aexit__
  |     raise BaseExceptionGroup(
  | exceptiongroup.ExceptionGroup: unhandled errors in a TaskGroup (1 sub-exception)
  +-+---------------- 1 ----------------
    | Traceback (most recent call last):
    |   File "c:\Users\jht56\anaconda3\envs\backend\lib\site-packages\starlette\middleware\errors.py", line 164, in __call__
    |     await self.app(scope, receive, _send)
    |   File "c:\Users\jht56\anaconda3\envs\backend\lib\site-packages\starlette\middleware\base.py", line 189, in __call__
    |     with collapse_excgroups():
    |   File "c:\Users\jht56\anaconda3\envs\backend\lib\contextlib.py", line 153, in __exit__
    |     self.gen.throw(typ, value, traceback)
    |   File "c:\Users\jht56\anaconda3\envs\backend\lib\site-packages\starlette\_utils.py", line 93, in collapse_excgroups
    |     raise exc
    |   File "c:\Users\jht56\anaconda3\envs\backend\lib\site-packages\starlette\middleware\base.py", line 191, in __call__
    |     response = await self.dispatch_func(request, call_next)
    |   File "C:\Users\jht56\Documents\GitHub\fastapi-core\src\common\middleware\base.py", line 68, in auth_middleware
    |     user = decode_jwt_token(token) if token else None
    |   File "C:\Users\jht56\Documents\GitHub\fastapi-core\src\auth\service.py", line 184, in decode_jwt_token
    |     raise UnauthorizedException("토큰이 만료되었습니다.")
    | common.exceptions.base.UnauthorizedException: 401: 토큰이 만료되었습니다.
    +------------------------------------

During handling of the above exception, another exception occurred:

Traceback (most recent call last):
  File "c:\Users\jht56\anaconda3\envs\backend\lib\site-packages\starlette\middleware\errors.py", line 164, in __call__
    await self.app(scope, receive, _send)
  File "c:\Users\jht56\anaconda3\envs\backend\lib\site-packages\starlette\middleware\base.py", line 189, in __call__
    with collapse_excgroups():
  File "c:\Users\jht56\anaconda3\envs\backend\lib\contextlib.py", line 153, in __exit__
    self.gen.throw(typ, value, traceback)
  File "c:\Users\jht56\anaconda3\envs\backend\lib\site-packages\starlette\_utils.py", line 93, in collapse_excgroups
    raise exc
  File "c:\Users\jht56\anaconda3\envs\backend\lib\site-packages\starlette\middleware\base.py", line 191, in __call__
    response = await self.dispatch_func(request, call_next)
  File "C:\Users\jht56\Documents\GitHub\fastapi-core\src\common\middleware\base.py", line 68, in auth_middleware
    user = decode_jwt_token(token) if token else None
  File "C:\Users\jht56\Documents\GitHub\fastapi-core\src\auth\service.py", line 184, in decode_jwt_token
    raise UnauthorizedException("토큰이 만료되었습니다.")
common.exceptions.base.UnauthorizedException: 401: 토큰이 만료되었습니다.
2025-04-08 19:56:30,642 [ERROR] [req_id:None user:None] handlers.py:101 - Unexpected server error: 401: 토큰이 만료되었습니다. | POST /auth/token/access
  + Exception Group Traceback (most recent call last):
  |   File "c:\Users\jht56\anaconda3\envs\backend\lib\site-packages\starlette\_utils.py", line 87, in collapse_excgroups
  |     yield
  |   File "c:\Users\jht56\anaconda3\envs\backend\lib\site-packages\starlette\middleware\base.py", line 190, in __call__
  |     async with anyio.create_task_group() as task_group:
  |   File "c:\Users\jht56\anaconda3\envs\backend\lib\site-packages\anyio\_backends\_asyncio.py", line 767, in __aexit__
  |     raise BaseExceptionGroup(
  | exceptiongroup.ExceptionGroup: unhandled errors in a TaskGroup (1 sub-exception)
  +-+---------------- 1 ----------------
    | Traceback (most recent call last):
    |   File "c:\Users\jht56\anaconda3\envs\backend\lib\site-packages\starlette\middleware\errors.py", line 164, in __call__
    |     await self.app(scope, receive, _send)
    |   File "c:\Users\jht56\anaconda3\envs\backend\lib\site-packages\starlette\middleware\base.py", line 189, in __call__
    |     with collapse_excgroups():
    |   File "c:\Users\jht56\anaconda3\envs\backend\lib\contextlib.py", line 153, in __exit__
    |     self.gen.throw(typ, value, traceback)
    |   File "c:\Users\jht56\anaconda3\envs\backend\lib\site-packages\starlette\_utils.py", line 93, in collapse_excgroups
    |     raise exc
    |   File "c:\Users\jht56\anaconda3\envs\backend\lib\site-packages\starlette\middleware\base.py", line 191, in __call__
    |     response = await self.dispatch_func(request, call_next)
    |   File "C:\Users\jht56\Documents\GitHub\fastapi-core\src\common\middleware\base.py", line 68, in auth_middleware
    |     user = decode_jwt_token(token) if token else None
    |   File "C:\Users\jht56\Documents\GitHub\fastapi-core\src\auth\service.py", line 184, in decode_jwt_token
    |     raise UnauthorizedException("토큰이 만료되었습니다.")
    | common.exceptions.base.UnauthorizedException: 401: 토큰이 만료되었습니다.
    +------------------------------------

During handling of the above exception, another exception occurred:

Traceback (most recent call last):
  File "c:\Users\jht56\anaconda3\envs\backend\lib\site-packages\starlette\middleware\errors.py", line 164, in __call__
    await self.app(scope, receive, _send)
  File "c:\Users\jht56\anaconda3\envs\backend\lib\site-packages\starlette\middleware\base.py", line 189, in __call__
    with collapse_excgroups():
  File "c:\Users\jht56\anaconda3\envs\backend\lib\contextlib.py", line 153, in __exit__
    self.gen.throw(typ, value, traceback)
  File "c:\Users\jht56\anaconda3\envs\backend\lib\site-packages\starlette\_utils.py", line 93, in collapse_excgroups
    raise exc
  File "c:\Users\jht56\anaconda3\envs\backend\lib\site-packages\starlette\middleware\base.py", line 191, in __call__
    response = await self.dispatch_func(request, call_next)
  File "C:\Users\jht56\Documents\GitHub\fastapi-core\src\common\middleware\base.py", line 68, in auth_middleware
    user = decode_jwt_token(token) if token else None
  File "C:\Users\jht56\Documents\GitHub\fastapi-core\src\auth\service.py", line 184, in decode_jwt_token
    raise UnauthorizedException("토큰이 만료되었습니다.")
common.exceptions.base.UnauthorizedException: 401: 토큰이 만료되었습니다.
2025-04-08 20:05:59,663 [ERROR] [req_id:None user:None] handlers.py:101 - Unexpected server error: 401: 토큰이 만료되었습니다. | POST /auth/token/access
  + Exception Group Traceback (most recent call last):
  |   File "c:\Users\jht56\anaconda3\envs\backend\lib\site-packages\starlette\_utils.py", line 87, in collapse_excgroups
  |     yield
  |   File "c:\Users\jht56\anaconda3\envs\backend\lib\site-packages\starlette\middleware\base.py", line 190, in __call__
  |     async with anyio.create_task_group() as task_group:
  |   File "c:\Users\jht56\anaconda3\envs\backend\lib\site-packages\anyio\_backends\_asyncio.py", line 767, in __aexit__
  |     raise BaseExceptionGroup(
  | exceptiongroup.ExceptionGroup: unhandled errors in a TaskGroup (1 sub-exception)
  +-+---------------- 1 ----------------
    | Traceback (most recent call last):
    |   File "c:\Users\jht56\anaconda3\envs\backend\lib\site-packages\starlette\middleware\errors.py", line 164, in __call__
    |     await self.app(scope, receive, _send)
    |   File "c:\Users\jht56\anaconda3\envs\backend\lib\site-packages\starlette\middleware\base.py", line 189, in __call__
    |     with collapse_excgroups():
    |   File "c:\Users\jht56\anaconda3\envs\backend\lib\contextlib.py", line 153, in __exit__
    |     self.gen.throw(typ, value, traceback)
    |   File "c:\Users\jht56\anaconda3\envs\backend\lib\site-packages\starlette\_utils.py", line 93, in collapse_excgroups
    |     raise exc
    |   File "c:\Users\jht56\anaconda3\envs\backend\lib\site-packages\starlette\middleware\base.py", line 191, in __call__
    |     response = await self.dispatch_func(request, call_next)
    |   File "C:\Users\jht56\Documents\GitHub\fastapi-core\src\common\middleware\base.py", line 68, in auth_middleware
    |   File "C:\Users\jht56\Documents\GitHub\fastapi-core\src\auth\service.py", line 184, in decode_jwt_token
    |     raise UnauthorizedException("토큰이 만료되었습니다.")
    | common.exceptions.base.UnauthorizedException: 401: 토큰이 만료되었습니다.
    +------------------------------------

During handling of the above exception, another exception occurred:

Traceback (most recent call last):
  File "c:\Users\jht56\anaconda3\envs\backend\lib\site-packages\starlette\middleware\errors.py", line 164, in __call__
    await self.app(scope, receive, _send)
  File "c:\Users\jht56\anaconda3\envs\backend\lib\site-packages\starlette\middleware\base.py", line 189, in __call__
    with collapse_excgroups():
  File "c:\Users\jht56\anaconda3\envs\backend\lib\contextlib.py", line 153, in __exit__
    self.gen.throw(typ, value, traceback)
  File "c:\Users\jht56\anaconda3\envs\backend\lib\site-packages\starlette\_utils.py", line 93, in collapse_excgroups
    raise exc
  File "c:\Users\jht56\anaconda3\envs\backend\lib\site-packages\starlette\middleware\base.py", line 191, in __call__
    response = await self.dispatch_func(request, call_next)
  File "C:\Users\jht56\Documents\GitHub\fastapi-core\src\common\middleware\base.py", line 68, in auth_middleware
  File "C:\Users\jht56\Documents\GitHub\fastapi-core\src\auth\service.py", line 184, in decode_jwt_token
    raise UnauthorizedException("토큰이 만료되었습니다.")
common.exceptions.base.UnauthorizedException: 401: 토큰이 만료되었습니다.
2025-04-08 20:06:03,454 [ERROR] [req_id:None user:None] handlers.py:101 - Unexpected server error: 401: 토큰이 만료되었습니다. | POST /auth/token/access
  + Exception Group Traceback (most recent call last):
  |   File "c:\Users\jht56\anaconda3\envs\backend\lib\site-packages\starlette\_utils.py", line 87, in collapse_excgroups
  |     yield
  |   File "c:\Users\jht56\anaconda3\envs\backend\lib\site-packages\starlette\middleware\base.py", line 190, in __call__
  |     async with anyio.create_task_group() as task_group:
  |   File "c:\Users\jht56\anaconda3\envs\backend\lib\site-packages\anyio\_backends\_asyncio.py", line 767, in __aexit__
  |     raise BaseExceptionGroup(
  | exceptiongroup.ExceptionGroup: unhandled errors in a TaskGroup (1 sub-exception)
  +-+---------------- 1 ----------------
    | Traceback (most recent call last):
    |   File "c:\Users\jht56\anaconda3\envs\backend\lib\site-packages\starlette\middleware\errors.py", line 164, in __call__
    |     await self.app(scope, receive, _send)
    |   File "c:\Users\jht56\anaconda3\envs\backend\lib\site-packages\starlette\middleware\base.py", line 189, in __call__
    |     with collapse_excgroups():
    |   File "c:\Users\jht56\anaconda3\envs\backend\lib\contextlib.py", line 153, in __exit__
    |     self.gen.throw(typ, value, traceback)
    |   File "c:\Users\jht56\anaconda3\envs\backend\lib\site-packages\starlette\_utils.py", line 93, in collapse_excgroups
    |     raise exc
    |   File "c:\Users\jht56\anaconda3\envs\backend\lib\site-packages\starlette\middleware\base.py", line 191, in __call__
    |     response = await self.dispatch_func(request, call_next)
    |   File "C:\Users\jht56\Documents\GitHub\fastapi-core\src\common\middleware\base.py", line 55, in auth_middleware
    |     user = decode_jwt_token(token) if token else None
    |   File "C:\Users\jht56\Documents\GitHub\fastapi-core\src\auth\service.py", line 184, in decode_jwt_token
    |     raise UnauthorizedException("토큰이 만료되었습니다.")
    | common.exceptions.base.UnauthorizedException: 401: 토큰이 만료되었습니다.
    +------------------------------------

During handling of the above exception, another exception occurred:

Traceback (most recent call last):
  File "c:\Users\jht56\anaconda3\envs\backend\lib\site-packages\starlette\middleware\errors.py", line 164, in __call__
    await self.app(scope, receive, _send)
  File "c:\Users\jht56\anaconda3\envs\backend\lib\site-packages\starlette\middleware\base.py", line 189, in __call__
    with collapse_excgroups():
  File "c:\Users\jht56\anaconda3\envs\backend\lib\contextlib.py", line 153, in __exit__
    self.gen.throw(typ, value, traceback)
  File "c:\Users\jht56\anaconda3\envs\backend\lib\site-packages\starlette\_utils.py", line 93, in collapse_excgroups
    raise exc
  File "c:\Users\jht56\anaconda3\envs\backend\lib\site-packages\starlette\middleware\base.py", line 191, in __call__
    response = await self.dispatch_func(request, call_next)
  File "C:\Users\jht56\Documents\GitHub\fastapi-core\src\common\middleware\base.py", line 55, in auth_middleware
    user = decode_jwt_token(token) if token else None
  File "C:\Users\jht56\Documents\GitHub\fastapi-core\src\auth\service.py", line 184, in decode_jwt_token
    raise UnauthorizedException("토큰이 만료되었습니다.")
common.exceptions.base.UnauthorizedException: 401: 토큰이 만료되었습니다.
2025-04-08 20:09:02,055 [ERROR] [req_id:None user:None] handlers.py:101 - Unexpected server error: 401: 토큰이 만료되었습니다. | POST /auth/token/access
  + Exception Group Traceback (most recent call last):
  |   File "c:\Users\jht56\anaconda3\envs\backend\lib\site-packages\starlette\_utils.py", line 87, in collapse_excgroups
  |     yield
  |   File "c:\Users\jht56\anaconda3\envs\backend\lib\site-packages\starlette\middleware\base.py", line 190, in __call__
  |     async with anyio.create_task_group() as task_group:
  |   File "c:\Users\jht56\anaconda3\envs\backend\lib\site-packages\anyio\_backends\_asyncio.py", line 767, in __aexit__
  |     raise BaseExceptionGroup(
  | exceptiongroup.ExceptionGroup: unhandled errors in a TaskGroup (1 sub-exception)
  +-+---------------- 1 ----------------
    | Traceback (most recent call last):
    |   File "c:\Users\jht56\anaconda3\envs\backend\lib\site-packages\starlette\middleware\errors.py", line 164, in __call__
    |     await self.app(scope, receive, _send)
    |   File "c:\Users\jht56\anaconda3\envs\backend\lib\site-packages\starlette\middleware\base.py", line 189, in __call__
    |     with collapse_excgroups():
    |   File "c:\Users\jht56\anaconda3\envs\backend\lib\contextlib.py", line 153, in __exit__
    |     self.gen.throw(typ, value, traceback)
    |   File "c:\Users\jht56\anaconda3\envs\backend\lib\site-packages\starlette\_utils.py", line 93, in collapse_excgroups
    |     raise exc
    |   File "c:\Users\jht56\anaconda3\envs\backend\lib\site-packages\starlette\middleware\base.py", line 191, in __call__
    |     response = await self.dispatch_func(request, call_next)
    |   File "C:\Users\jht56\Documents\GitHub\fastapi-core\src\common\middleware\base.py", line 55, in auth_middleware
    |     try:
    |   File "C:\Users\jht56\Documents\GitHub\fastapi-core\src\auth\service.py", line 184, in decode_jwt_token
    |     raise UnauthorizedException("토큰이 만료되었습니다.")
    | common.exceptions.base.UnauthorizedException: 401: 토큰이 만료되었습니다.
    +------------------------------------

During handling of the above exception, another exception occurred:

Traceback (most recent call last):
  File "c:\Users\jht56\anaconda3\envs\backend\lib\site-packages\starlette\middleware\errors.py", line 164, in __call__
    await self.app(scope, receive, _send)
  File "c:\Users\jht56\anaconda3\envs\backend\lib\site-packages\starlette\middleware\base.py", line 189, in __call__
    with collapse_excgroups():
  File "c:\Users\jht56\anaconda3\envs\backend\lib\contextlib.py", line 153, in __exit__
    self.gen.throw(typ, value, traceback)
  File "c:\Users\jht56\anaconda3\envs\backend\lib\site-packages\starlette\_utils.py", line 93, in collapse_excgroups
    raise exc
  File "c:\Users\jht56\anaconda3\envs\backend\lib\site-packages\starlette\middleware\base.py", line 191, in __call__
    response = await self.dispatch_func(request, call_next)
  File "C:\Users\jht56\Documents\GitHub\fastapi-core\src\common\middleware\base.py", line 55, in auth_middleware
    try:
  File "C:\Users\jht56\Documents\GitHub\fastapi-core\src\auth\service.py", line 184, in decode_jwt_token
    raise UnauthorizedException("토큰이 만료되었습니다.")
common.exceptions.base.UnauthorizedException: 401: 토큰이 만료되었습니다.
2025-04-08 20:09:05,911 [ERROR] [req_id:None user:None] handlers.py:101 - Unexpected server error: 401: 토큰이 만료되었습니다. | POST /auth/token/access
  + Exception Group Traceback (most recent call last):
  |   File "c:\Users\jht56\anaconda3\envs\backend\lib\site-packages\starlette\_utils.py", line 87, in collapse_excgroups
  |     yield
  |   File "c:\Users\jht56\anaconda3\envs\backend\lib\site-packages\starlette\middleware\base.py", line 190, in __call__
  |     async with anyio.create_task_group() as task_group:
  |   File "c:\Users\jht56\anaconda3\envs\backend\lib\site-packages\anyio\_backends\_asyncio.py", line 767, in __aexit__
  |     raise BaseExceptionGroup(
  | exceptiongroup.ExceptionGroup: unhandled errors in a TaskGroup (1 sub-exception)
  +-+---------------- 1 ----------------
    | Traceback (most recent call last):
    |   File "c:\Users\jht56\anaconda3\envs\backend\lib\site-packages\starlette\middleware\errors.py", line 164, in __call__
    |     await self.app(scope, receive, _send)
    |   File "c:\Users\jht56\anaconda3\envs\backend\lib\site-packages\starlette\middleware\base.py", line 189, in __call__
    |     with collapse_excgroups():
    |   File "c:\Users\jht56\anaconda3\envs\backend\lib\contextlib.py", line 153, in __exit__
    |     self.gen.throw(typ, value, traceback)
    |   File "c:\Users\jht56\anaconda3\envs\backend\lib\site-packages\starlette\_utils.py", line 93, in collapse_excgroups
    |     raise exc
    |   File "c:\Users\jht56\anaconda3\envs\backend\lib\site-packages\starlette\middleware\base.py", line 191, in __call__
    |     response = await self.dispatch_func(request, call_next)
    |   File "C:\Users\jht56\Documents\GitHub\fastapi-core\src\common\middleware\base.py", line 61, in auth_middleware
    |     raise exc
    |   File "C:\Users\jht56\Documents\GitHub\fastapi-core\src\common\middleware\base.py", line 56, in auth_middleware
    |     user = decode_jwt_token(token) if token else None
    |   File "C:\Users\jht56\Documents\GitHub\fastapi-core\src\auth\service.py", line 184, in decode_jwt_token
    |     raise UnauthorizedException("토큰이 만료되었습니다.")
    | common.exceptions.base.UnauthorizedException: 401: 토큰이 만료되었습니다.
    +------------------------------------

During handling of the above exception, another exception occurred:

Traceback (most recent call last):
  File "c:\Users\jht56\anaconda3\envs\backend\lib\site-packages\starlette\middleware\errors.py", line 164, in __call__
    await self.app(scope, receive, _send)
  File "c:\Users\jht56\anaconda3\envs\backend\lib\site-packages\starlette\middleware\base.py", line 189, in __call__
    with collapse_excgroups():
  File "c:\Users\jht56\anaconda3\envs\backend\lib\contextlib.py", line 153, in __exit__
    self.gen.throw(typ, value, traceback)
  File "c:\Users\jht56\anaconda3\envs\backend\lib\site-packages\starlette\_utils.py", line 93, in collapse_excgroups
    raise exc
  File "c:\Users\jht56\anaconda3\envs\backend\lib\site-packages\starlette\middleware\base.py", line 191, in __call__
    response = await self.dispatch_func(request, call_next)
  File "C:\Users\jht56\Documents\GitHub\fastapi-core\src\common\middleware\base.py", line 61, in auth_middleware
    raise exc
  File "C:\Users\jht56\Documents\GitHub\fastapi-core\src\common\middleware\base.py", line 56, in auth_middleware
    user = decode_jwt_token(token) if token else None
  File "C:\Users\jht56\Documents\GitHub\fastapi-core\src\auth\service.py", line 184, in decode_jwt_token
    raise UnauthorizedException("토큰이 만료되었습니다.")
common.exceptions.base.UnauthorizedException: 401: 토큰이 만료되었습니다.
2025-04-08 20:11:16,751 [ERROR] [req_id:None user:None] handlers.py:101 - Unexpected server error: 401: 토큰이 만료되었습니다. | POST /auth/token/access
  + Exception Group Traceback (most recent call last):
  |   File "c:\Users\jht56\anaconda3\envs\backend\lib\site-packages\starlette\_utils.py", line 87, in collapse_excgroups
  |     yield
  |   File "c:\Users\jht56\anaconda3\envs\backend\lib\site-packages\starlette\middleware\base.py", line 190, in __call__
  |     async with anyio.create_task_group() as task_group:
  |   File "c:\Users\jht56\anaconda3\envs\backend\lib\site-packages\anyio\_backends\_asyncio.py", line 767, in __aexit__
  |     raise BaseExceptionGroup(
  | exceptiongroup.ExceptionGroup: unhandled errors in a TaskGroup (1 sub-exception)
  +-+---------------- 1 ----------------
    | Traceback (most recent call last):
    |   File "c:\Users\jht56\anaconda3\envs\backend\lib\site-packages\starlette\middleware\errors.py", line 164, in __call__
    |     await self.app(scope, receive, _send)
    |   File "c:\Users\jht56\anaconda3\envs\backend\lib\site-packages\starlette\middleware\base.py", line 189, in __call__
    |     with collapse_excgroups():
    |   File "c:\Users\jht56\anaconda3\envs\backend\lib\contextlib.py", line 153, in __exit__
    |     self.gen.throw(typ, value, traceback)
    |   File "c:\Users\jht56\anaconda3\envs\backend\lib\site-packages\starlette\_utils.py", line 93, in collapse_excgroups
    |     raise exc
    |   File "c:\Users\jht56\anaconda3\envs\backend\lib\site-packages\starlette\middleware\base.py", line 191, in __call__
    |     response = await self.dispatch_func(request, call_next)
    |   File "C:\Users\jht56\Documents\GitHub\fastapi-core\src\common\middleware\base.py", line 61, in auth_middleware
    |     except Exception as e:
    |   File "C:\Users\jht56\Documents\GitHub\fastapi-core\src\common\middleware\base.py", line 56, in auth_middleware
    |     user = decode_jwt_token(token) if token else None
    |   File "C:\Users\jht56\Documents\GitHub\fastapi-core\src\auth\service.py", line 184, in decode_jwt_token
    |     raise UnauthorizedException("토큰이 만료되었습니다.")
    | common.exceptions.base.UnauthorizedException: 401: 토큰이 만료되었습니다.
    +------------------------------------

During handling of the above exception, another exception occurred:

Traceback (most recent call last):
  File "c:\Users\jht56\anaconda3\envs\backend\lib\site-packages\starlette\middleware\errors.py", line 164, in __call__
    await self.app(scope, receive, _send)
  File "c:\Users\jht56\anaconda3\envs\backend\lib\site-packages\starlette\middleware\base.py", line 189, in __call__
    with collapse_excgroups():
  File "c:\Users\jht56\anaconda3\envs\backend\lib\contextlib.py", line 153, in __exit__
    self.gen.throw(typ, value, traceback)
  File "c:\Users\jht56\anaconda3\envs\backend\lib\site-packages\starlette\_utils.py", line 93, in collapse_excgroups
    raise exc
  File "c:\Users\jht56\anaconda3\envs\backend\lib\site-packages\starlette\middleware\base.py", line 191, in __call__
    response = await self.dispatch_func(request, call_next)
  File "C:\Users\jht56\Documents\GitHub\fastapi-core\src\common\middleware\base.py", line 61, in auth_middleware
    except Exception as e:
  File "C:\Users\jht56\Documents\GitHub\fastapi-core\src\common\middleware\base.py", line 56, in auth_middleware
    user = decode_jwt_token(token) if token else None
  File "C:\Users\jht56\Documents\GitHub\fastapi-core\src\auth\service.py", line 184, in decode_jwt_token
    raise UnauthorizedException("토큰이 만료되었습니다.")
common.exceptions.base.UnauthorizedException: 401: 토큰이 만료되었습니다.
2025-04-08 20:11:21,091 [WARNING] [req_id:None user:None] base.py:66 - [AUTH] 인증 실패: 401: 토큰이 만료되었습니다.
2025-04-08 20:11:52,376 [WARNING] [req_id:None user:None] base.py:66 - [AUTH] 인증 실패: 401: 토큰이 만료되었습니다.
2025-04-08 20:11:56,616 [WARNING] [req_id:None user:None] base.py:66 - [AUTH] 인증 실패: 401: 토큰이 만료되었습니다.
2025-04-08 20:16:04,477 [WARNING] [req_id:None user:None] base.py:66 - [AUTH] 인증 실패: 401: 토큰이 만료되었습니다.
2025-04-08 20:16:08,906 [WARNING] [req_id:None user:None] base.py:80 - [AUTH] 인증 실패: 401: 토큰이 만료되었습니다.
2025-04-08 20:16:31,834 [DEBUG] [req_id:52204cfd-93f2-41b7-a8fd-4ad3722e1fb7 user:None] connection.py:951 - caching sha2: succeeded by fast path.
2025-04-08 20:16:32,012 [WARNING] [req_id:52204cfd-93f2-41b7-a8fd-4ad3722e1fb7 user:None] handlers.py:15 - Handled AppException: UNAUTHORIZED - 비밀번호가 일치하지 않습니다.
2025-04-08 20:16:32,013 [INFO] [req_id:52204cfd-93f2-41b7-a8fd-4ad3722e1fb7 user:None] base.py:43 - POST /auth/login/email [401] 0.2184s
2025-04-08 20:16:38,489 [DEBUG] [req_id:b7f15268-ba74-4eea-b122-abec6f374f33 user:None] connection.py:951 - caching sha2: succeeded by fast path.
2025-04-08 20:16:38,545 [WARNING] [req_id:b7f15268-ba74-4eea-b122-abec6f374f33 user:None] handlers.py:15 - Handled AppException: CONFLICT - 이미 등록된 email입니다.
2025-04-08 20:16:38,547 [INFO] [req_id:b7f15268-ba74-4eea-b122-abec6f374f33 user:None] base.py:43 - POST /auth/register/email [409] 0.0962s
2025-04-08 20:16:48,340 [WARNING] [req_id:86bc4543-45a0-4e95-a03b-307b572a69d1 user:None] handlers.py:35 - Validation failed: [{'type': 'value_error', 'loc': ('body',), 'msg': 'Value error, email, login_id, phone 중 하나는 반드시 입력해야 합니다.', 'input': {'nickname': 'test8', 'password': '1234'}, 'ctx': {'error': ValueError('email, login_id, phone 중 하나는 반드시 입력해야 합니다.')}}]
2025-04-08 20:16:48,341 [INFO] [req_id:86bc4543-45a0-4e95-a03b-307b572a69d1 user:None] base.py:43 - POST /auth/register/email [422] 0.0161s
2025-04-08 20:17:06,022 [WARNING] [req_id:2286e1c4-ece5-42e2-8593-d25058c86365 user:None] handlers.py:15 - Handled AppException: CONFLICT - 이미 등록된 nickname입니다.
2025-04-08 20:17:06,023 [INFO] [req_id:2286e1c4-ece5-42e2-8593-d25058c86365 user:None] base.py:43 - POST /auth/register/login_id [409] 0.0186s
2025-04-08 20:17:11,319 [WARNING] [req_id:a382ca48-85e9-4855-b0ab-2e0a023296e5 user:None] handlers.py:35 - Validation failed: [{'type': 'missing', 'loc': ('body', 'nickname'), 'msg': 'Field required', 'input': {'login_id': 'diajd2', 'password': '1234'}}]
2025-04-08 20:17:11,320 [INFO] [req_id:a382ca48-85e9-4855-b0ab-2e0a023296e5 user:None] base.py:43 - POST /auth/register/login_id [422] 0.0047s
2025-04-08 20:20:47,778 [WARNING] [req_id:f73097a3-b0fe-4f61-8a06-4dbd94c9d730 user:None] handlers.py:35 - Validation failed: [{'type': 'missing', 'loc': ('body', 'nickname'), 'msg': 'Field required', 'input': {'login_id': 'diajd2', 'password': '1234'}}]
2025-04-08 20:20:47,779 [INFO] [req_id:f73097a3-b0fe-4f61-8a06-4dbd94c9d730 user:None] base.py:43 - POST /auth/register/login_id [422] 0.01s
2025-04-08 20:21:37,837 [WARNING] [req_id:844973fa-acc9-4bcd-a555-bc14d8498d04 user:None] handlers.py:35 - Validation failed: [{'type': 'missing', 'loc': ('body', 'nickname'), 'msg': 'Field required', 'input': {'login_id': 'diajd2', 'password': '1234'}}]
2025-04-08 20:21:37,839 [INFO] [req_id:844973fa-acc9-4bcd-a555-bc14d8498d04 user:None] base.py:43 - POST /auth/register/login_id [422] 0.0075s
2025-04-08 20:21:46,823 [WARNING] [req_id:de507bea-5ff6-4374-9940-a255ead11b6e user:None] handlers.py:35 - Validation failed: [{'type': 'missing', 'loc': ('body', 'nickname'), 'msg': 'Field required', 'input': {'login_id': 'diajd2', 'password': '1234'}}]
2025-04-08 20:21:46,825 [INFO] [req_id:de507bea-5ff6-4374-9940-a255ead11b6e user:None] base.py:43 - POST /auth/register/login_id [422] 0.0083s
2025-04-08 20:22:05,504 [WARNING] [req_id:9698f1e5-f72c-48ac-a70e-262353f62aee user:None] handlers.py:35 - Validation failed: [{'type': 'missing', 'loc': ('body', 'nickname'), 'msg': 'Field required', 'input': {'login_id': 'diajd2', 'password': '1234'}}]
2025-04-08 20:22:05,505 [INFO] [req_id:9698f1e5-f72c-48ac-a70e-262353f62aee user:None] base.py:43 - POST /auth/register/login_id [422] 0.0098s
2025-04-08 20:24:33,971 [WARNING] [req_id:652c9cd7-a137-45d0-9765-4e1f666989fc user:None] handlers.py:35 - Validation failed: [{'type': 'missing', 'loc': ('body', 'nickname'), 'msg': 'Field required', 'input': {'login_id': 'diajd2', 'password': '1234'}}]
2025-04-08 20:24:33,973 [INFO] [req_id:652c9cd7-a137-45d0-9765-4e1f666989fc user:None] base.py:43 - POST /auth/register/login_id [422] 0.0063s
2025-04-08 20:24:42,899 [DEBUG] [req_id:8f5b6a7d-3989-4ef1-ba48-04233d1e2988 user:None] connection.py:951 - caching sha2: succeeded by fast path.
2025-04-08 20:24:43,044 [WARNING] [req_id:8f5b6a7d-3989-4ef1-ba48-04233d1e2988 user:None] base.py:46 - [REQUEST_LOGGER] 처리 실패: 1 validation error for UserSchema
nickname
  Input should be a valid string [type=string_type, input_value=None, input_type=NoneType]
    For further information visit https://errors.pydantic.dev/2.10/v/string_type
2025-04-08 20:24:54,531 [WARNING] [req_id:541ff265-141e-4348-b56d-a6d39cb57724 user:None] handlers.py:15 - Handled AppException: CONFLICT - 이미 등록된 login_id입니다.
2025-04-08 20:24:54,532 [INFO] [req_id:541ff265-141e-4348-b56d-a6d39cb57724 user:None] base.py:43 - POST /auth/register/login_id [409] 0.0201s
2025-04-08 20:25:22,056 [WARNING] [req_id:88b7fdfc-c74f-48a9-9630-0e2363de67da user:None] base.py:46 - [REQUEST_LOGGER] 처리 실패: 1 validation error for UserSchema
nickname
  Input should be a valid string [type=string_type, input_value=None, input_type=NoneType]
    For further information visit https://errors.pydantic.dev/2.10/v/string_type
2025-04-08 20:27:49,790 [WARNING] [req_id:7a3ea510-1ed8-4bf1-a263-813b3fea6945 user:None] handlers.py:15 - Handled AppException: CONFLICT - 이미 등록된 login_id입니다.
2025-04-08 20:27:49,792 [INFO] [req_id:7a3ea510-1ed8-4bf1-a263-813b3fea6945 user:None] base.py:43 - POST /auth/register/login_id [409] 0.0182s
2025-04-08 20:27:55,206 [DEBUG] [req_id:7b42875c-510f-4c18-a800-787d0a336d9d user:None] connection.py:951 - caching sha2: succeeded by fast path.
2025-04-08 20:27:55,261 [WARNING] [req_id:7b42875c-510f-4c18-a800-787d0a336d9d user:None] handlers.py:15 - Handled AppException: CONFLICT - 이미 등록된 login_id입니다.
2025-04-08 20:27:55,262 [INFO] [req_id:7b42875c-510f-4c18-a800-787d0a336d9d user:None] base.py:43 - POST /auth/register/login_id [409] 0.0908s
2025-04-08 20:27:57,669 [INFO] [req_id:cf115c34-55fe-4009-9581-0a9077944589 user:None] base.py:43 - POST /auth/register/login_id [200] 0.1083s
2025-04-08 20:28:03,829 [WARNING] [req_id:ca927d73-6805-4865-a109-9d6ecbd61002 user:None] handlers.py:35 - Validation failed: [{'type': 'string_too_short', 'loc': ('body', 'login_id'), 'msg': 'String should have at least 4 characters', 'input': 'd', 'ctx': {'min_length': 4}}]
2025-04-08 20:28:03,830 [INFO] [req_id:ca927d73-6805-4865-a109-9d6ecbd61002 user:None] base.py:43 - POST /auth/register/login_id [422] 0.0061s
2025-04-08 20:28:17,657 [WARNING] [req_id:None user:None] base.py:80 - [AUTH] 인증 실패: 401: 토큰이 만료되었습니다.
2025-04-08 20:28:21,939 [DEBUG] [req_id:3ec9540a-7ce1-4e3b-831a-02b4a147c253 user:None] connection.py:951 - caching sha2: succeeded by fast path.
2025-04-08 20:28:21,985 [WARNING] [req_id:3ec9540a-7ce1-4e3b-831a-02b4a147c253 user:None] handlers.py:15 - Handled AppException: NOT_FOUND - User not found
2025-04-08 20:28:21,986 [INFO] [req_id:3ec9540a-7ce1-4e3b-831a-02b4a147c253 user:None] base.py:43 - POST /auth/login/login_id [404] 0.0789s
2025-04-08 20:28:38,015 [INFO] [req_id:f7037915-3eee-465e-bea6-973b27bc25ff user:None] base.py:43 - POST /auth/login/login_id [200] 0.087s
2025-04-08 20:29:02,042 [WARNING] [req_id:None user:None] base.py:80 - [AUTH] 인증 실패: 1 validation error for UserTokenSchema
email
  Input should be a valid string [type=string_type, input_value=None, input_type=NoneType]
    For further information visit https://errors.pydantic.dev/2.10/v/string_type
2025-04-08 20:45:19,709 [WARNING] [req_id:None user:None] base.py:80 - [AUTH] 인증 실패: 1 validation error for UserTokenSchema
email
  Input should be a valid string [type=string_type, input_value=None, input_type=NoneType]
    For further information visit https://errors.pydantic.dev/2.10/v/string_type
2025-04-08 21:17:21,365 [WARNING] [req_id:None user:None] base.py:80 - [AUTH] 인증 실패: 1 validation error for UserTokenSchema
email
  Input should be a valid string [type=string_type, input_value=None, input_type=NoneType]
    For further information visit https://errors.pydantic.dev/2.10/v/string_type
2025-04-08 21:17:25,946 [WARNING] [req_id:None user:None] base.py:80 - [AUTH] 인증 실패: 1 validation error for LoginUserSchema
  Value error, email, login_id, phone 중 정확히 하나만 입력해야 합니다. [type=value_error, input_value={'id': 13, 'email': None,...d': None, 'phone': None}, input_type=dict]
    For further information visit https://errors.pydantic.dev/2.10/v/value_error
2025-04-08 21:17:28,797 [WARNING] [req_id:None user:None] base.py:80 - [AUTH] 인증 실패: 1 validation error for LoginUserSchema
  Value error, email, login_id, phone 중 정확히 하나만 입력해야 합니다. [type=value_error, input_value={'id': 13, 'email': None,...d': None, 'phone': None}, input_type=dict]
    For further information visit https://errors.pydantic.dev/2.10/v/value_error
2025-04-08 21:18:15,805 [DEBUG] [req_id:5117d686-ef45-4e01-8d05-387faeaade3f user:None] connection.py:951 - caching sha2: succeeded by fast path.
2025-04-08 21:18:15,948 [WARNING] [req_id:5117d686-ef45-4e01-8d05-387faeaade3f user:None] handlers.py:15 - Handled AppException: UNAUTHORIZED - 비밀번호가 일치하지 않습니다.
2025-04-08 21:18:15,950 [INFO] [req_id:5117d686-ef45-4e01-8d05-387faeaade3f user:None] base.py:43 - POST /auth/login/email [401] 0.1845s
2025-04-08 21:18:21,203 [INFO] [req_id:07bca435-a49b-4728-8185-a56cb0569392 user:None] base.py:43 - POST /auth/login/email [200] 0.1439s
2025-04-08 21:18:29,234 [INFO] [req_id:713d6f54-0a83-44e1-98b2-96852eb42a5e user:None] base.py:43 - POST /auth/login/login_id [200] 0.0769s
2025-04-08 21:18:37,963 [WARNING] [req_id:7f71f669-d070-4fb1-a49c-5c160f779d15 user:None] handlers.py:15 - Handled AppException: CONFLICT - 이미 등록된 email입니다.
2025-04-08 21:18:37,964 [INFO] [req_id:7f71f669-d070-4fb1-a49c-5c160f779d15 user:None] base.py:43 - POST /auth/register/email [409] 0.0151s
2025-04-08 21:18:41,176 [WARNING] [req_id:7bd0e3c6-59c8-4c78-8b43-86c05d2c33ee user:None] handlers.py:15 - Handled AppException: CONFLICT - 이미 등록된 nickname입니다.
2025-04-08 21:18:41,177 [INFO] [req_id:7bd0e3c6-59c8-4c78-8b43-86c05d2c33ee user:None] base.py:43 - POST /auth/register/email [409] 0.017s
2025-04-08 21:18:44,728 [INFO] [req_id:0a32f71d-2487-4c1a-97fb-ef2b729b518f user:None] base.py:43 - POST /auth/register/email [200] 0.1186s
2025-04-08 21:18:47,768 [WARNING] [req_id:db93a409-b21a-4e30-af2e-83d4c0891872 user:None] handlers.py:35 - Validation failed: [{'type': 'value_error', 'loc': ('body',), 'msg': 'Value error, email, login_id, phone 중 하나는 반드시 입력해야 합니다.', 'input': {'nickname': 'tesst8', 'password': '1234'}, 'ctx': {'error': ValueError('email, login_id, phone 중 하나는 반드시 입력해야 합니다.')}}]
2025-04-08 21:18:47,769 [INFO] [req_id:db93a409-b21a-4e30-af2e-83d4c0891872 user:None] base.py:43 - POST /auth/register/email [422] 0.0052s
2025-04-08 21:18:51,684 [WARNING] [req_id:fb5fca8b-3025-448b-bcd9-0876133eb640 user:None] handlers.py:15 - Handled AppException: CONFLICT - 이미 등록된 email입니다.
2025-04-08 21:18:51,685 [INFO] [req_id:fb5fca8b-3025-448b-bcd9-0876133eb640 user:None] base.py:43 - POST /auth/register/email [409] 0.0135s
2025-04-08 21:18:57,501 [WARNING] [req_id:None user:None] base.py:80 - [AUTH] 인증 실패: 401: 유효하지 않은 토큰입니다.
2025-04-08 21:19:02,450 [INFO] [req_id:466e5b72-f8b3-42ff-b788-0b5ae2289c93 user:None] base.py:43 - POST /auth/login/email [200] 0.0971s
2025-04-08 21:19:04,691 [INFO] [req_id:9f552828-35c9-4ce8-853b-190a2033cb95 user:1] base.py:43 - POST /auth/logout [200] 0.0071s
2025-04-08 21:19:11,952 [WARNING] [req_id:None user:None] base.py:80 - [AUTH] 인증 실패: 1 validation error for LoginUserSchema
  Value error, email, login_id, phone 중 정확히 하나만 입력해야 합니다. [type=value_error, input_value={'id': 13, 'email': None,...d': None, 'phone': None}, input_type=dict]
    For further information visit https://errors.pydantic.dev/2.10/v/value_error
2025-04-08 21:20:57,033 [WARNING] [req_id:None user:None] base.py:80 - [AUTH] 인증 실패: 1 validation error for LoginUserSchema
  Value error, email, login_id, phone 중 정확히 하나만 입력해야 합니다. [type=value_error, input_value={'id': 13, 'email': None,...d': None, 'phone': None}, input_type=dict]
    For further information visit https://errors.pydantic.dev/2.10/v/value_error
2025-04-08 21:20:59,533 [WARNING] [req_id:None user:None] base.py:80 - [AUTH] 인증 실패: 1 validation error for LoginUserSchema
  Value error, email, login_id, phone 중 정확히 하나만 입력해야 합니다. [type=value_error, input_value={'id': 13, 'email': None,...d': None, 'phone': None}, input_type=dict]
    For further information visit https://errors.pydantic.dev/2.10/v/value_error
2025-04-08 21:22:36,964 [INFO] [req_id:17c5c9e0-26ef-4edd-892c-7e07aa948ed0 user:None] base.py:43 - POST /auth/login/email [200] 49.4971s
2025-04-08 21:23:46,536 [INFO] [req_id:5ef440f1-4dfb-4d73-b668-643861705f91 user:1] base.py:43 - POST /auth/token/access [200] 18.4936s
2025-04-08 21:24:03,595 [INFO] [req_id:2617677f-ced7-4b05-9ec3-d0bcc6fc9889 user:None] base.py:43 - POST /auth/login/login_id [200] 10.3338s
2025-04-08 21:24:32,115 [WARNING] [req_id:edd9dcb8-adaa-41a2-a098-752ecebe160b user:None] handlers.py:15 - Handled AppException: NOT_FOUND - User not found
2025-04-08 21:24:32,117 [INFO] [req_id:edd9dcb8-adaa-41a2-a098-752ecebe160b user:None] base.py:43 - POST /auth/login/phone [404] 0.0193s
2025-04-08 21:25:26,463 [INFO] [req_id:f41ffff3-a33d-4643-8740-05d0d37b0efa user:None] base.py:43 - POST /auth/login/phone [200] 27.8049s
2025-04-08 21:26:00,585 [INFO] [req_id:60d3ef7a-6a09-4039-ad33-8b0915b4409b user:None] base.py:43 - POST /auth/login/phone [200] 17.1611s
2025-04-08 21:27:48,418 [INFO] [req_id:73e62272-a3ea-4316-aa66-e4f6fa9cd42e user:None] base.py:43 - POST /auth/login/phone [200] 96.8596s
2025-04-08 21:32:20,366 [DEBUG] [req_id:2ad27d80-a9f9-4eb2-8971-38e408fb4410 user:None] connection.py:951 - caching sha2: succeeded by fast path.
2025-04-08 21:33:09,967 [INFO] [req_id:2ad27d80-a9f9-4eb2-8971-38e408fb4410 user:None] base.py:43 - POST /auth/login/phone [200] 49.6316s
2025-04-08 21:33:14,175 [DEBUG] [req_id:9a140fc1-598c-4b65-a733-89b3278940c9 user:None] connection.py:951 - caching sha2: succeeded by fast path.
2025-04-08 21:33:19,707 [INFO] [req_id:9a140fc1-598c-4b65-a733-89b3278940c9 user:None] base.py:43 - POST /auth/login/phone [200] 5.5639s
2025-04-08 21:33:24,174 [INFO] [req_id:6d0936d8-c857-4869-a252-e61a2f660fec user:None] base.py:43 - POST /auth/login/email [200] 0.133s
2025-04-08 21:33:27,234 [INFO] [req_id:a58366b5-d438-4f1c-a1f4-5d6392ba0231 user:None] base.py:43 - POST /auth/login/login_id [200] 0.0761s
2025-04-08 21:33:30,345 [INFO] [req_id:a2fb4f8e-3782-4782-b112-4811b31c702c user:None] base.py:43 - POST /auth/login/phone [200] 0.0738s
2025-04-08 21:33:45,405 [INFO] [req_id:4ea86dde-f225-44cf-8ea5-29554cbf5fe2 user:None] base.py:43 - POST /auth/login/phone [200] 0.0798s
2025-04-08 21:34:12,086 [INFO] [req_id:3fb1b583-65db-4fae-81ac-9743259f0fe6 user:8] base.py:43 - POST /auth/token/access [200] 0.0075s
2025-04-08 21:35:29,805 [INFO] [req_id:9c3c5dbc-120b-4a0d-9a6b-d12c649838ef user:8] base.py:43 - POST /auth/token/access [200] 61.1158s
2025-04-08 21:35:36,337 [INFO] [req_id:dc681e2a-14e8-4fb9-ab44-24b7bb8e057a user:None] base.py:43 - POST /auth/login/login_id [200] 0.0825s
2025-04-08 21:35:45,563 [WARNING] [req_id:4e23b657-ae64-428e-965b-c5d5b17245b7 user:13] handlers.py:76 - Unhandled HTTPException: 401 - 토큰에 이메일 정보가 없습니다. | POST /auth/token/access
2025-04-08 21:35:45,564 [INFO] [req_id:4e23b657-ae64-428e-965b-c5d5b17245b7 user:13] base.py:43 - POST /auth/token/access [401] 0.0063s
2025-04-08 21:40:00,088 [WARNING] [req_id:e162c66c-e834-47a1-bac4-63d8bf319f62 user:13] handlers.py:76 - Unhandled HTTPException: 401 - 토큰에 이메일 정보가 없습니다. | POST /auth/token/access
2025-04-08 21:40:00,090 [INFO] [req_id:e162c66c-e834-47a1-bac4-63d8bf319f62 user:13] base.py:43 - POST /auth/token/access [401] 0.007s
2025-04-08 21:40:09,616 [INFO] [req_id:e00bc56c-d32b-4038-8274-8035153fb11c user:13] base.py:43 - POST /auth/token/access [200] 4.2438s
2025-04-08 21:40:27,897 [INFO] [req_id:d39ba178-b0e5-4f03-b031-cd31a4f3cc73 user:13] base.py:43 - POST /auth/token/access [200] 11.1038s
2025-04-08 21:40:35,263 [INFO] [req_id:389ce9c0-5288-4afe-a7aa-1bda7ed7fa97 user:13] base.py:43 - POST /auth/token/access [200] 3.2731s
2025-04-08 21:41:01,470 [INFO] [req_id:d9ced705-c160-4736-964c-508d5deb2fd4 user:13] base.py:43 - POST /auth/token/access [200] 14.1438s
2025-04-08 21:41:06,969 [DEBUG] [req_id:aff19999-d8ef-45f4-87c7-782b38c0cbcb user:None] connection.py:951 - caching sha2: succeeded by fast path.
2025-04-08 21:41:17,332 [INFO] [req_id:aff19999-d8ef-45f4-87c7-782b38c0cbcb user:None] base.py:43 - POST /auth/login/email [200] 10.3798s
2025-04-08 21:41:21,294 [WARNING] [req_id:630d05c8-dbd7-4c2b-8533-73afa0fe86ac user:None] base.py:46 - [REQUEST_LOGGER] 처리 실패: 1 validation error for UserSchema
email
  value is not a valid email address: An email address must have an @-sign. [type=value_error, input_value='', input_type=str]
2025-04-08 21:43:12,539 [WARNING] [req_id:76108248-44c0-4693-9381-f318f29d4a37 user:None] base.py:46 - [REQUEST_LOGGER] 처리 실패: 1 validation error for UserSchema
email
  value is not a valid email address: An email address must have an @-sign. [type=value_error, input_value='', input_type=str]
2025-04-08 21:43:40,445 [INFO] [req_id:9ae1ad7c-24eb-470a-9911-d4072b3537dd user:None] base.py:43 - POST /auth/login/login_id [200] 0.0826s
2025-04-08 21:43:42,916 [WARNING] [req_id:a56ff80c-f72b-480f-8a3a-7cf77d09ff48 user:None] base.py:46 - [REQUEST_LOGGER] 처리 실패: 1 validation error for UserSchema
email
  value is not a valid email address: An email address must have an @-sign. [type=value_error, input_value='', input_type=str]
2025-04-08 21:44:10,182 [WARNING] [req_id:c7f66d21-4781-4d24-8596-422db757f585 user:None] base.py:46 - [REQUEST_LOGGER] 처리 실패: 1 validation error for UserSchema
email
  value is not a valid email address: An email address must have an @-sign. [type=value_error, input_value='', input_type=str]
2025-04-08 21:45:49,882 [WARNING] [req_id:6eb1e4c8-c735-46b4-ad30-8428d4d184b2 user:None] base.py:46 - [REQUEST_LOGGER] 처리 실패: 1 validation error for UserSchema
email
  value is not a valid email address: An email address must have an @-sign. [type=value_error, input_value='', input_type=str]
2025-04-08 21:46:39,682 [WARNING] [req_id:8b820108-1cf1-4388-bc54-d8af719e2da2 user:None] base.py:46 - [REQUEST_LOGGER] 처리 실패: 1 validation error for UserSchema
email
  value is not a valid email address: An email address must have an @-sign. [type=value_error, input_value='', input_type=str]
2025-04-08 21:52:22,121 [WARNING] [req_id:847acd90-6f9e-46ef-a3a2-621a3236668e user:None] base.py:46 - [REQUEST_LOGGER] 처리 실패: 1 validation error for UserSchema
email
  value is not a valid email address: An email address must have an @-sign. [type=value_error, input_value='(NULL)', input_type=str]
2025-04-08 21:52:27,738 [DEBUG] [req_id:89cfacea-6f16-4b43-a498-43bfc91f915f user:None] connection.py:951 - caching sha2: succeeded by fast path.
2025-04-08 21:52:27,860 [INFO] [req_id:89cfacea-6f16-4b43-a498-43bfc91f915f user:None] base.py:43 - POST /auth/login/login_id [200] 0.151s
2025-04-08 21:52:30,769 [WARNING] [req_id:c0cff4f9-6daf-4e9c-9121-291568faf739 user:None] base.py:46 - [REQUEST_LOGGER] 처리 실패: 1 validation error for UserSchema
email
  value is not a valid email address: An email address must have an @-sign. [type=value_error, input_value='(NULL)', input_type=str]
2025-04-08 21:53:07,237 [INFO] [req_id:e1737a00-fade-42e6-b918-6df2bf361673 user:None] base.py:43 - POST /auth/register/phone [200] 0.1139s
2025-04-08 21:53:26,525 [INFO] [req_id:b700434b-b2eb-48fb-bcd5-7ef343b0629a user:None] base.py:43 - POST /auth/login/phone [200] 6.2896s
2025-04-08 21:55:18,590 [INFO] [req_id:26993ac8-e9ec-44e6-8a08-b7ead7a02953 user:None] base.py:43 - POST /auth/login/phone [200] 0.078s
2025-04-08 21:55:21,320 [INFO] [req_id:058e2616-64f4-4a1f-9947-e027f28fab00 user:None] base.py:43 - POST /auth/login/login_id [200] 0.0767s
2025-04-08 22:06:23,035 [INFO] [req_id:8b451672-fd4f-422c-8256-e3ad9c9b5409 user:None] base.py:43 - POST /auth/login/email [200] 0.1538s
2025-04-08 22:06:25,002 [INFO] [req_id:c428801c-e920-483e-ab92-abc04c3565b9 user:None] base.py:43 - POST /auth/login/login_id [200] 0.0756s
2025-04-08 22:06:27,803 [INFO] [req_id:67d14dfc-4c63-4e6e-99e1-bbd55e23174d user:None] base.py:43 - POST /auth/login/phone [200] 0.0681s
2025-04-08 22:06:33,591 [WARNING] [req_id:7dbeae8b-bc88-4f44-b42f-d524d30a0dc8 user:None] handlers.py:15 - Handled AppException: CONFLICT - 이미 등록된 email입니다.
2025-04-08 22:06:33,593 [INFO] [req_id:7dbeae8b-bc88-4f44-b42f-d524d30a0dc8 user:None] base.py:43 - POST /auth/register/email [409] 0.015s
2025-04-08 22:06:37,178 [WARNING] [req_id:62c9ebe8-bfed-4cd3-8a3c-288b162014a1 user:None] handlers.py:15 - Handled AppException: CONFLICT - 이미 등록된 nickname입니다.
2025-04-08 22:06:37,179 [INFO] [req_id:62c9ebe8-bfed-4cd3-8a3c-288b162014a1 user:None] base.py:43 - POST /auth/register/email [409] 0.0198s
2025-04-08 22:06:39,029 [WARNING] [req_id:c4274f50-2391-4fd7-9909-79d69e2f8667 user:None] handlers.py:35 - Validation failed: [{'type': 'value_error', 'loc': ('body',), 'msg': 'Value error, email, login_id, phone 중 하나는 반드시 입력해야 합니다.', 'input': {'nickname': 'tesst8', 'password': '1234'}, 'ctx': {'error': ValueError('email, login_id, phone 중 하나는 반드시 입력해야 합니다.')}}]
2025-04-08 22:06:39,030 [INFO] [req_id:c4274f50-2391-4fd7-9909-79d69e2f8667 user:None] base.py:43 - POST /auth/register/email [422] 0.0041s
2025-04-08 22:07:10,416 [WARNING] [req_id:7442f477-e8aa-49c1-a6e2-7dc7f711c4dd user:None] handlers.py:35 - Validation failed: [{'type': 'string_too_short', 'loc': ('body', 'login_id'), 'msg': 'String should have at least 4 characters', 'input': 'd', 'ctx': {'min_length': 4}}]
2025-04-08 22:07:10,417 [INFO] [req_id:7442f477-e8aa-49c1-a6e2-7dc7f711c4dd user:None] base.py:43 - POST /auth/register/login_id [422] 0.0035s
2025-04-08 22:07:13,616 [INFO] [req_id:0b839d87-b0c0-4d9c-8216-fea89baa290b user:None] base.py:43 - POST /auth/register/login_id [200] 0.092s
2025-04-08 22:07:29,763 [INFO] [req_id:5393346a-ca65-4b45-a40c-68da81102e7c user:18] base.py:43 - POST /auth/token/access [200] 0.006s
2025-04-08 22:07:33,879 [INFO] [req_id:10c2597f-63bd-40cc-9c7f-d7fbed2216d8 user:18] base.py:43 - POST /auth/token/refresh [200] 0.005s
2025-04-08 22:07:37,714 [INFO] [req_id:3da67cf8-e0e9-4b1d-a475-183aab06d116 user:18] base.py:43 - POST /auth/logout [200] 0.0073s
2025-04-08 22:27:28,129 [DEBUG] [req_id:cc28144b-0637-4be1-bfd7-380bf71a18a7 user:None] connection.py:951 - caching sha2: succeeded by fast path.
2025-04-08 22:27:28,225 [INFO] [req_id:cc28144b-0637-4be1-bfd7-380bf71a18a7 user:None] base.py:43 - POST /auth/login/login_id [200] 0.1089s
2025-04-08 22:27:37,985 [INFO] [req_id:5e65d9c9-afef-4574-bcd7-7b235aa3a674 user:1] base.py:43 - POST /auth/token/access [200] 0.007s
2025-04-08 22:28:52,118 [INFO] [req_id:fb6c536e-c8e9-42da-8d71-f2065d81e6b8 user:None] base.py:43 - POST /auth/login/login_id [200] 49.706s
2025-04-08 22:34:00,365 [INFO] [req_id:acaea44a-47d1-45f8-86f7-7e4d98c5ac64 user:None] base.py:43 - POST /auth/login/login_id [200] 303.1824s
2025-04-08 22:36:31,198 [DEBUG] [req_id:dc58a0ee-27c6-4222-9767-03c9f708febd user:None] connection.py:951 - caching sha2: succeeded by fast path.
2025-04-08 22:36:31,360 [WARNING] [req_id:dc58a0ee-27c6-4222-9767-03c9f708febd user:None] base.py:46 - [REQUEST_LOGGER] 처리 실패: 1 validation error for LoginIdLoginSchema
  Input should be a valid dictionary or instance of LoginIdLoginSchema [type=model_type, input_value=UserSchema(id=1, nickname...RolesEnum.USER: 'USER'>), input_type=UserSchema]
    For further information visit https://errors.pydantic.dev/2.10/v/model_type
2025-04-08 22:37:34,318 [WARNING] [req_id:f99c4ed6-6f31-444b-91d1-b0f20c6fdbcf user:None] base.py:46 - [REQUEST_LOGGER] 처리 실패: 1 validation error for LoginIdLoginSchema
  Input should be a valid dictionary or instance of LoginIdLoginSchema [type=model_type, input_value=UserSchema(id=1, nickname...RolesEnum.USER: 'USER'>), input_type=UserSchema]
    For further information visit https://errors.pydantic.dev/2.10/v/model_type
2025-04-08 22:37:37,998 [DEBUG] [req_id:02af8786-22f9-4cee-bccb-2b6853ac582e user:None] connection.py:951 - caching sha2: succeeded by fast path.
2025-04-08 22:37:38,132 [WARNING] [req_id:02af8786-22f9-4cee-bccb-2b6853ac582e user:None] base.py:46 - [REQUEST_LOGGER] 처리 실패: 1 validation error for LoginIdLoginSchema
  Input should be a valid dictionary or instance of LoginIdLoginSchema [type=model_type, input_value=UserSchema(id=1, nickname...RolesEnum.USER: 'USER'>), input_type=UserSchema]
    For further information visit https://errors.pydantic.dev/2.10/v/model_type
2025-04-08 22:37:49,899 [WARNING] [req_id:d4502ffe-558f-4e85-8563-fc5fbbd67d18 user:None] base.py:46 - [REQUEST_LOGGER] 처리 실패: 1 validation error for LoginIdLoginSchema
  Input should be a valid dictionary or instance of LoginIdLoginSchema [type=model_type, input_value=UserSchema(id=1, nickname...RolesEnum.USER: 'USER'>), input_type=UserSchema]
    For further information visit https://errors.pydantic.dev/2.10/v/model_type
2025-04-08 22:37:53,615 [DEBUG] [req_id:a4e5628f-f5a5-444e-b342-ce2a87bd44e0 user:None] connection.py:951 - caching sha2: succeeded by fast path.
2025-04-08 22:38:08,317 [INFO] [req_id:a4e5628f-f5a5-444e-b342-ce2a87bd44e0 user:None] base.py:43 - POST /auth/login/login_id [200] 14.7267s
2025-04-08 22:38:29,194 [WARNING] [req_id:b16fab71-76b2-4028-ab53-17581673c900 user:None] base.py:46 - [REQUEST_LOGGER] 처리 실패: 1 validation error for EmailLoginSchema
  Input should be a valid dictionary or instance of EmailLoginSchema [type=model_type, input_value=UserSchema(id=1, nickname...RolesEnum.USER: 'USER'>), input_type=UserSchema]
    For further information visit https://errors.pydantic.dev/2.10/v/model_type
2025-04-08 22:38:33,275 [DEBUG] [req_id:2459c579-82fa-40ba-99d5-bd17158829f0 user:None] connection.py:951 - caching sha2: succeeded by fast path.
2025-04-08 22:38:53,429 [INFO] [req_id:2459c579-82fa-40ba-99d5-bd17158829f0 user:None] base.py:43 - POST /auth/login/email [200] 20.1807s
2025-04-08 22:39:10,615 [INFO] [req_id:541131d6-2dc5-4192-918a-2a5d5bb44ae1 user:None] base.py:43 - POST /auth/login/phone [200] 13.8104s
2025-04-08 22:39:20,711 [INFO] [req_id:1ec7cb5d-d06f-46aa-9f81-5785c8a836ac user:None] base.py:43 - POST /auth/login/login_id [200] 3.4868s
2025-04-08 22:39:29,172 [INFO] [req_id:e4e53220-69da-4b2e-ad17-23040327cbd0 user:None] base.py:43 - POST /auth/login/login_id [200] 6.6797s
2025-04-08 22:39:35,629 [INFO] [req_id:06180131-a3ad-4841-9f51-b7b3ed3d4343 user:None] base.py:43 - POST /auth/login/login_id [200] 0.0941s
2025-04-08 22:40:40,312 [INFO] [req_id:9b04a794-49ec-4cd3-904c-e1601b49f288 user:1] base.py:43 - POST /auth/token/access [200] 0.0065s
2025-04-08 22:40:45,298 [INFO] [req_id:f959c939-86e7-45dc-a258-fb6420e6ea59 user:1] base.py:43 - POST /auth/token/refresh [200] 0.009s
2025-04-08 22:41:03,592 [INFO] [req_id:18bd593e-4fbd-4c10-af36-f89f08112fba user:None] base.py:43 - POST /auth/login/email [200] 0.0891s
2025-04-08 22:41:29,836 [WARNING] [req_id:536ce433-281a-4dd4-b95f-b2b36c061afd user:1] handlers.py:15 - Handled AppException: UNAUTHORIZED - 유효하지 않은 Refresh Token 입니다.
2025-04-08 22:41:29,838 [INFO] [req_id:536ce433-281a-4dd4-b95f-b2b36c061afd user:1] base.py:43 - POST /auth/token/refresh [401] 0.0081s
2025-04-08 22:42:50,575 [WARNING] [req_id:a596b348-8ed4-40f2-b9e2-9e8378032ca7 user:1] handlers.py:15 - Handled AppException: UNAUTHORIZED - 유효하지 않은 Refresh Token 입니다.
2025-04-08 22:42:50,577 [INFO] [req_id:a596b348-8ed4-40f2-b9e2-9e8378032ca7 user:1] base.py:43 - POST /auth/token/refresh [401] 0.0109s
2025-04-08 22:42:56,886 [WARNING] [req_id:08df3a0f-998c-4b37-9ae7-9ddf25697a95 user:1] handlers.py:15 - Handled AppException: UNAUTHORIZED - 유효하지 않은 Refresh Token 입니다.
2025-04-08 22:42:56,887 [INFO] [req_id:08df3a0f-998c-4b37-9ae7-9ddf25697a95 user:1] base.py:43 - POST /auth/token/refresh [401] 0.006s
2025-04-08 22:43:02,465 [INFO] [req_id:afbc3bee-c197-4c5b-acde-93b762c626d8 user:None] base.py:43 - POST /auth/login/login_id [200] 0.1005s
2025-04-08 22:43:30,964 [INFO] [req_id:affbed83-c22b-49b7-95bb-8b3b487a9aac user:1] base.py:43 - POST /auth/token/refresh [200] 19.5625s
2025-04-08 22:43:46,054 [WARNING] [req_id:94138ab7-1ea0-425c-a87b-f5385d529e0f user:1] handlers.py:15 - Handled AppException: UNAUTHORIZED - 유효하지 않은 Refresh Token 입니다.
2025-04-08 22:43:46,055 [INFO] [req_id:94138ab7-1ea0-425c-a87b-f5385d529e0f user:1] base.py:43 - POST /auth/token/refresh [401] 0.0115s
2025-04-08 22:46:16,116 [INFO] [req_id:30082d4c-382f-490e-9860-e058a0c7111c user:1] base.py:43 - POST /auth/token/refresh [200] 2.574s
2025-04-08 22:46:19,667 [WARNING] [req_id:79bdedd0-7ea5-4cd8-ae47-6b993f4e9083 user:1] handlers.py:15 - Handled AppException: UNAUTHORIZED - 유효하지 않은 Refresh Token 입니다.
2025-04-08 22:46:19,668 [INFO] [req_id:79bdedd0-7ea5-4cd8-ae47-6b993f4e9083 user:1] base.py:43 - POST /auth/token/refresh [401] 0.0147s
2025-04-08 22:54:12,010 [WARNING] [req_id:f42a7fb9-2e58-401d-837b-2621a2b457f8 user:1] handlers.py:15 - Handled AppException: UNAUTHORIZED - 유효하지 않은 Refresh Token 입니다.
2025-04-08 22:54:12,013 [INFO] [req_id:f42a7fb9-2e58-401d-837b-2621a2b457f8 user:1] base.py:43 - POST /auth/token/refresh [401] 0.0078s
2025-04-08 22:54:16,000 [DEBUG] [req_id:de66c620-5cb8-4502-b60e-16137abe583e user:None] connection.py:951 - caching sha2: succeeded by fast path.
2025-04-08 22:54:16,149 [INFO] [req_id:de66c620-5cb8-4502-b60e-16137abe583e user:None] base.py:43 - POST /auth/login/login_id [200] 0.1807s
2025-04-08 22:54:29,164 [INFO] [req_id:da622e04-146c-49be-a515-df020be23f9d user:1] base.py:43 - POST /auth/token/refresh [200] 5.6181s
